{
  "clarke_review": {
    "primary_code": "NAMEERROR_DURING_COLLECTION",
    "primary_message": "Pytest collection aborts due to a NameError raised at import time in the test module: \"E   NameError: name 'result' is not defined\".",
    "evidence": [
      "____ ERROR collecting tests/functional/test_epic_a_data_model_functional.py ____",
      "tests/functional/test_epic_a_data_model_functional.py:2549: in <module>",
      "E   NameError: name 'result' is not defined"
    ],
    "ada_change_correlation": {
      "suspected_cause_from_ada": "",
      "justification": ""
    },
    "explicit_actions_for_ada": [
      {
        "type": "revert_file",
        "path": "tests/functional/test_epic_a_data_model_functional.py"
      }
    ]
  },
  "final_decision": {
    "continue": false
  }
}