============================= test session starts ==============================
platform linux -- Python 3.10.12, pytest-8.4.1, pluggy-1.6.0
rootdir: /home/codex/schofield
plugins: mock-3.14.1, anyio-4.9.0, cov-6.2.1, langsmith-0.4.1
collected 190 items

tests/architectural/test_epic_a_data_model_architecture.py ............. [  6%]
..............                                                           [ 14%]
tests/functional/test_epic_a_data_model_functional.py ...........F....F. [ 23%]
.F...........FF.FxFF.......FFFFFFFFFFFFFFFFFFFFFFFFFFFFFFFFFFFFFFFFFFFFF [ 61%]
FFFFF.F.F.F..F..F.F.....FFFFFFFFFFFFFFFFFFFFFF........F..F..F..F..F...F. [ 99%]
.                                                                        [100%]

=================================== FAILURES ===================================
_____________ test_7_2_1_12_migration_journal_includes_timestamps ______________

    def test_7_2_1_12_migration_journal_includes_timestamps():
        """Verifies 7.2.1.12 — Migration journal entries include ISO-8601 UTC timestamps."""
        result = run_migrate_cli(["--section", "7.2.1.12"])
        outputs = result.get("outputs") or {}
        journal = outputs.get("migration_journal") or []
        # Assert: both entries include applied_at in canonical form and are non-decreasing
        times = [j.get("applied_at") for j in journal]
>       assert all(re.match(r"^\d{4}-\d{2}-\d{2}T\d{2}:\d{2}:\d{2}Z$", t or "") for t in times)
E       assert False
E        +  where False = all(<generator object test_7_2_1_12_migration_journal_includes_timestamps.<locals>.<genexpr> at 0x7ff0bce544a0>)

tests/functional/test_epic_a_data_model_functional.py:829: AssertionError
______________ test_7_2_1_17_deterministic_ordering_of_artefacts _______________

    def test_7_2_1_17_deterministic_ordering_of_artefacts():
        """Verifies 7.2.1.17 — Deterministic ordering across entities, fields, and journal."""
        result = run_migrate_cli(["--section", "7.2.1.17"])
        outputs = result.get("outputs") or {}
        entities = outputs.get("entities") or []
        # Assert: entities ascending by name
        names = [e.get("name") for e in entities]
        assert names == sorted(names)
        # Assert: fields for Response ascending by name
        response = next((e for e in entities if e.get("name") == "Response"), {})
        field_names = [f.get("name") for f in (response.get("fields") or [])]
        assert field_names == sorted(field_names)
        # Assert: journal non-decreasing by applied_at
        journal = outputs.get("migration_journal") or []
        times = [j.get("applied_at") for j in journal]
>       assert times == sorted(times)
E       TypeError: '<' not supported between instances of 'NoneType' and 'NoneType'

tests/functional/test_epic_a_data_model_functional.py:891: TypeError
____________________ test_7_2_2_3_erd_spec_schema_mismatch _____________________

mocker = <pytest_mock.plugin.MockerFixture object at 0x7ff0be057760>

    def test_7_2_2_3_erd_spec_schema_mismatch(mocker):
        """Verifies 7.2.2.3 — ERD spec schema mismatch."""
        # Mock: valid JSON wrong shape, then pretend validator flags missing properties.
        payload = json.dumps({"entities": [{"table_name": "Response"}]})
    
        class _FH:
            def read(self):
                return payload
    
            def __enter__(self):
                return self
    
            def __exit__(self, *args: Any) -> None:  # pragma: no cover
                return None
    
        mocker.patch("builtins.open", return_value=_FH())
        # Mock: schema validator boundary exists (not invoked by shim yet) and must be called
>       import tests.functional.test_epic_a_data_model_functional as mod

tests/functional/test_epic_a_data_model_functional.py:978: 
_ _ _ _ _ _ _ _ _ _ _ _ _ _ _ _ _ _ _ _ _ _ _ _ _ _ _ _ _ _ _ _ _ _ _ _ _ _ _ _ 
<frozen importlib._bootstrap>:1027: in _find_and_load
    ???
<frozen importlib._bootstrap>:1006: in _find_and_load_unlocked
    ???
<frozen importlib._bootstrap>:688: in _load_unlocked
    ???
../.local/lib/python3.10/site-packages/_pytest/assertion/rewrite.py:174: in exec_module
    co = _read_pyc(fn, pyc, state.trace)
_ _ _ _ _ _ _ _ _ _ _ _ _ _ _ _ _ _ _ _ _ _ _ _ _ _ _ _ _ _ _ _ _ _ _ _ _ _ _ _ 

source = PosixPath('/home/codex/schofield/tests/functional/test_epic_a_data_model_functional.py')
pyc = PosixPath('/home/codex/schofield/tests/functional/__pycache__/test_epic_a_data_model_functional.cpython-310-pytest-8.4.1.pyc')
trace = <pluggy._tracing.TagTracerSub object at 0x7ff0bfffb0d0>

    def _read_pyc(
        source: Path, pyc: Path, trace: Callable[[str], None] = lambda x: None
    ) -> types.CodeType | None:
        """Possibly read a pytest pyc containing rewritten code.
    
        Return rewritten code if successful or None if not.
        """
        try:
            fp = open(pyc, "rb")
        except OSError:
            return None
        with fp:
            try:
                stat_result = os.stat(source)
                mtime = int(stat_result.st_mtime)
                size = stat_result.st_size
>               data = fp.read(16)
E               TypeError: test_7_2_2_3_erd_spec_schema_mismatch.<locals>._FH.read() takes 1 positional argument but 2 were given

../.local/lib/python3.10/site-packages/_pytest/assertion/rewrite.py:379: TypeError
______________ test_7_3_1_6_direct_lookup_follows_row_validation _______________

mocker = <pytest_mock.plugin.MockerFixture object at 0x7ff0bdda6c50>

    def test_7_3_1_6_direct_lookup_follows_row_validation(mocker):
        """Verifies 7.3.1.6 — Direct lookup follows row validation."""
        order: List[str] = []
        # Patch boundary: validate_row then PlaceholderResolver.lookup_by_code
        import app.db.base as base
        mocker.patch.object(base, "DBSession", create=True)
        validate_row = mocker.patch.object(base.DBSession, "validate_row", side_effect=lambda *a, **k: order.append("validate_row"))
        import tests.functional.test_epic_a_data_model_functional as mod
        lookup = mocker.patch.object(mod.PlaceholderResolver, "lookup_by_code", side_effect=lambda *a, **k: order.append("lookup_by_code"))
        _ = run_migrate_cli(["--section", "7.3.1.6"])  # no-op call
        # Assert: direct lookup invoked only after validation completes
>       assert order == ["validate_row", "lookup_by_code"]
E       AssertionError: assert ['validate_row'] == ['validate_ro...okup_by_code']
E         
E         Right contains one more item: 'lookup_by_code'
E         
E         Full diff:
E           [
E               'validate_row',
E         -     'lookup_by_code',
E           ]

tests/functional/test_epic_a_data_model_functional.py:1328: AssertionError
__________ test_7_3_1_7_placeholder_resolution_follows_direct_lookup ___________

mocker = <pytest_mock.plugin.MockerFixture object at 0x7ff0bcfc44f0>

    def test_7_3_1_7_placeholder_resolution_follows_direct_lookup(mocker):
        """Verifies 7.3.1.7 — Placeholder resolution follows direct lookup."""
        order: List[str] = []
        # Patch boundary: PlaceholderResolver.lookup_by_code then Resolver.resolve_placeholders
        import tests.functional.test_epic_a_data_model_functional as mod
        lookup = mocker.patch.object(mod.PlaceholderResolver, "lookup_by_code", side_effect=lambda *a, **k: order.append("lookup_by_code"))
        resolve = mocker.patch.object(mod.Resolver, "resolve_placeholders", side_effect=lambda *a, **k: order.append("resolve_placeholders"))
        _ = run_migrate_cli(["--section", "7.3.1.7"])  # no-op call
        # Assert: resolution occurs only after direct lookup completes
>       assert order == ["lookup_by_code", "resolve_placeholders"]
E       AssertionError: assert [] == ['lookup_by_c...placeholders']
E         
E         Right contains 2 more items, first extra item: 'lookup_by_code'
E         
E         Full diff:
E         + []
E         - [
E         -     'lookup_by_code',
E         -     'resolve_placeholders',
E         - ]

tests/functional/test_epic_a_data_model_functional.py:1342: AssertionError
______________ test_7_3_1_9_determinism_check_precedes_next_step _______________

thing = <module 'app' from '/home/codex/schofield/app/__init__.py'>
comp = 'determinism', import_path = 'app.determinism'

    def _dot_lookup(thing, comp, import_path):
        try:
>           return getattr(thing, comp)
E           AttributeError: module 'app' has no attribute 'determinism'

/usr/lib/python3.10/unittest/mock.py:1248: AttributeError

During handling of the above exception, another exception occurred:

mocker = <pytest_mock.plugin.MockerFixture object at 0x7ff0bcdbf2e0>

    def test_7_3_1_9_determinism_check_precedes_next_step(mocker):
        """Verifies 7.3.1.9 — Determinism check precedes transition to the next step."""
        order: List[str] = []
        # Patch boundary: DeterminismChecker.verify precedes NextStep.start
>       determinism_check = mocker.patch(
            "app.determinism.checker.DeterminismChecker.verify",
            create=True,
            side_effect=lambda *a, **k: order.append("determinism_check"),
        )

tests/functional/test_epic_a_data_model_functional.py:1370: 
_ _ _ _ _ _ _ _ _ _ _ _ _ _ _ _ _ _ _ _ _ _ _ _ _ _ _ _ _ _ _ _ _ _ _ _ _ _ _ _ 
../.local/lib/python3.10/site-packages/pytest_mock/plugin.py:439: in __call__
    return self._start_patch(
../.local/lib/python3.10/site-packages/pytest_mock/plugin.py:257: in _start_patch
    mocked: MockType = p.start()
/usr/lib/python3.10/unittest/mock.py:1595: in start
    result = self.__enter__()
/usr/lib/python3.10/unittest/mock.py:1431: in __enter__
    self.target = self.getter()
/usr/lib/python3.10/unittest/mock.py:1618: in <lambda>
    getter = lambda: _importer(target)
/usr/lib/python3.10/unittest/mock.py:1261: in _importer
    thing = _dot_lookup(thing, comp, import_path)
_ _ _ _ _ _ _ _ _ _ _ _ _ _ _ _ _ _ _ _ _ _ _ _ _ _ _ _ _ _ _ _ _ _ _ _ _ _ _ _ 

thing = <module 'app' from '/home/codex/schofield/app/__init__.py'>
comp = 'determinism', import_path = 'app.determinism'

    def _dot_lookup(thing, comp, import_path):
        try:
            return getattr(thing, comp)
        except AttributeError:
>           __import__(import_path)
E           ModuleNotFoundError: No module named 'app.determinism'

/usr/lib/python3.10/unittest/mock.py:1250: ModuleNotFoundError
______________ test_7_3_1_11_template_registration_reuses_schema _______________

thing = <module 'app' from '/home/codex/schofield/app/__init__.py'>
comp = 'registry', import_path = 'app.registry'

    def _dot_lookup(thing, comp, import_path):
        try:
>           return getattr(thing, comp)
E           AttributeError: module 'app' has no attribute 'registry'

/usr/lib/python3.10/unittest/mock.py:1248: AttributeError

During handling of the above exception, another exception occurred:

mocker = <pytest_mock.plugin.MockerFixture object at 0x7ff0bd69f940>

    def test_7_3_1_11_template_registration_reuses_schema(mocker):
        """Verifies 7.3.1.11 — Template registration proceeds without schema migrations."""
        # Patch boundary: TemplateRegistry.register should be invoked once
>       register = mocker.patch(
            "app.registry.templates.TemplateRegistry.register",
            create=True,
            return_value=None,
        )

tests/functional/test_epic_a_data_model_functional.py:1395: 
_ _ _ _ _ _ _ _ _ _ _ _ _ _ _ _ _ _ _ _ _ _ _ _ _ _ _ _ _ _ _ _ _ _ _ _ _ _ _ _ 
../.local/lib/python3.10/site-packages/pytest_mock/plugin.py:439: in __call__
    return self._start_patch(
../.local/lib/python3.10/site-packages/pytest_mock/plugin.py:257: in _start_patch
    mocked: MockType = p.start()
/usr/lib/python3.10/unittest/mock.py:1595: in start
    result = self.__enter__()
/usr/lib/python3.10/unittest/mock.py:1431: in __enter__
    self.target = self.getter()
/usr/lib/python3.10/unittest/mock.py:1618: in <lambda>
    getter = lambda: _importer(target)
/usr/lib/python3.10/unittest/mock.py:1261: in _importer
    thing = _dot_lookup(thing, comp, import_path)
_ _ _ _ _ _ _ _ _ _ _ _ _ _ _ _ _ _ _ _ _ _ _ _ _ _ _ _ _ _ _ _ _ _ _ _ _ _ _ _ 

thing = <module 'app' from '/home/codex/schofield/app/__init__.py'>
comp = 'registry', import_path = 'app.registry'

    def _dot_lookup(thing, comp, import_path):
        try:
            return getattr(thing, comp)
        except AttributeError:
>           __import__(import_path)
E           ModuleNotFoundError: No module named 'app.registry'

/usr/lib/python3.10/unittest/mock.py:1250: ModuleNotFoundError
_______________ test_7_3_1_12_policy_registration_reuses_schema ________________

thing = <module 'app' from '/home/codex/schofield/app/__init__.py'>
comp = 'registry', import_path = 'app.registry'

    def _dot_lookup(thing, comp, import_path):
        try:
>           return getattr(thing, comp)
E           AttributeError: module 'app' has no attribute 'registry'

/usr/lib/python3.10/unittest/mock.py:1248: AttributeError

During handling of the above exception, another exception occurred:

mocker = <pytest_mock.plugin.MockerFixture object at 0x7ff0bcef7790>

    def test_7_3_1_12_policy_registration_reuses_schema(mocker):
        """Verifies 7.3.1.12 — Policy registration proceeds without schema migrations."""
        # Patch boundary: PolicyRegistry.register should be invoked once
>       policy_register = mocker.patch(
            "app.registry.policies.PolicyRegistry.register",
            create=True,
            return_value=None,
        )

tests/functional/test_epic_a_data_model_functional.py:1416: 
_ _ _ _ _ _ _ _ _ _ _ _ _ _ _ _ _ _ _ _ _ _ _ _ _ _ _ _ _ _ _ _ _ _ _ _ _ _ _ _ 
../.local/lib/python3.10/site-packages/pytest_mock/plugin.py:439: in __call__
    return self._start_patch(
../.local/lib/python3.10/site-packages/pytest_mock/plugin.py:257: in _start_patch
    mocked: MockType = p.start()
/usr/lib/python3.10/unittest/mock.py:1595: in start
    result = self.__enter__()
/usr/lib/python3.10/unittest/mock.py:1431: in __enter__
    self.target = self.getter()
/usr/lib/python3.10/unittest/mock.py:1618: in <lambda>
    getter = lambda: _importer(target)
/usr/lib/python3.10/unittest/mock.py:1261: in _importer
    thing = _dot_lookup(thing, comp, import_path)
_ _ _ _ _ _ _ _ _ _ _ _ _ _ _ _ _ _ _ _ _ _ _ _ _ _ _ _ _ _ _ _ _ _ _ _ _ _ _ _ 

thing = <module 'app' from '/home/codex/schofield/app/__init__.py'>
comp = 'registry', import_path = 'app.registry'

    def _dot_lookup(thing, comp, import_path):
        try:
            return getattr(thing, comp)
        except AttributeError:
>           __import__(import_path)
E           ModuleNotFoundError: No module named 'app.registry'

/usr/lib/python3.10/unittest/mock.py:1250: ModuleNotFoundError
_________________ test_7_3_2_8_halt_on_invalid_encryption_key __________________

thing = <module 'app' from '/home/codex/schofield/app/__init__.py'>
comp = 'encryption', import_path = 'app.encryption'

    def _dot_lookup(thing, comp, import_path):
        try:
>           return getattr(thing, comp)
E           AttributeError: module 'app' has no attribute 'encryption'

/usr/lib/python3.10/unittest/mock.py:1248: AttributeError

During handling of the above exception, another exception occurred:

mocker = <pytest_mock.plugin.MockerFixture object at 0x7ff0bcd88ca0>

    def test_7_3_2_8_halt_on_invalid_encryption_key(mocker):
        """Verifies 7.3.2.8 — Halt on invalid encryption key during field access (S3)."""
>       decrypt = mocker.patch("app.encryption.kms.decrypt_value", create=True, side_effect=RuntimeError("invalid key"))

tests/functional/test_epic_a_data_model_functional.py:1555: 
_ _ _ _ _ _ _ _ _ _ _ _ _ _ _ _ _ _ _ _ _ _ _ _ _ _ _ _ _ _ _ _ _ _ _ _ _ _ _ _ 
../.local/lib/python3.10/site-packages/pytest_mock/plugin.py:439: in __call__
    return self._start_patch(
../.local/lib/python3.10/site-packages/pytest_mock/plugin.py:257: in _start_patch
    mocked: MockType = p.start()
/usr/lib/python3.10/unittest/mock.py:1595: in start
    result = self.__enter__()
/usr/lib/python3.10/unittest/mock.py:1431: in __enter__
    self.target = self.getter()
/usr/lib/python3.10/unittest/mock.py:1618: in <lambda>
    getter = lambda: _importer(target)
/usr/lib/python3.10/unittest/mock.py:1261: in _importer
    thing = _dot_lookup(thing, comp, import_path)
_ _ _ _ _ _ _ _ _ _ _ _ _ _ _ _ _ _ _ _ _ _ _ _ _ _ _ _ _ _ _ _ _ _ _ _ _ _ _ _ 

thing = <module 'app' from '/home/codex/schofield/app/__init__.py'>
comp = 'encryption', import_path = 'app.encryption'

    def _dot_lookup(thing, comp, import_path):
        try:
            return getattr(thing, comp)
        except AttributeError:
>           __import__(import_path)
E           ModuleNotFoundError: No module named 'app.encryption'

/usr/lib/python3.10/unittest/mock.py:1250: ModuleNotFoundError
_______________ test_7_3_2_9_halt_when_tls_materials_unavailable _______________

thing = <module 'app' from '/home/codex/schofield/app/__init__.py'>
comp = 'security', import_path = 'app.security'

    def _dot_lookup(thing, comp, import_path):
        try:
>           return getattr(thing, comp)
E           AttributeError: module 'app' has no attribute 'security'

/usr/lib/python3.10/unittest/mock.py:1248: AttributeError

During handling of the above exception, another exception occurred:

mocker = <pytest_mock.plugin.MockerFixture object at 0x7ff0bd69c100>

    def test_7_3_2_9_halt_when_tls_materials_unavailable(mocker):
        """Verifies 7.3.2.9 — Halt when TLS materials unavailable (E4)."""
>       load_tls = mocker.patch("app.security.tls.load_materials", create=True, side_effect=RuntimeError("no tls materials"))

tests/functional/test_epic_a_data_model_functional.py:1568: 
_ _ _ _ _ _ _ _ _ _ _ _ _ _ _ _ _ _ _ _ _ _ _ _ _ _ _ _ _ _ _ _ _ _ _ _ _ _ _ _ 
../.local/lib/python3.10/site-packages/pytest_mock/plugin.py:439: in __call__
    return self._start_patch(
../.local/lib/python3.10/site-packages/pytest_mock/plugin.py:257: in _start_patch
    mocked: MockType = p.start()
/usr/lib/python3.10/unittest/mock.py:1595: in start
    result = self.__enter__()
/usr/lib/python3.10/unittest/mock.py:1431: in __enter__
    self.target = self.getter()
/usr/lib/python3.10/unittest/mock.py:1618: in <lambda>
    getter = lambda: _importer(target)
/usr/lib/python3.10/unittest/mock.py:1261: in _importer
    thing = _dot_lookup(thing, comp, import_path)
_ _ _ _ _ _ _ _ _ _ _ _ _ _ _ _ _ _ _ _ _ _ _ _ _ _ _ _ _ _ _ _ _ _ _ _ _ _ _ _ 

thing = <module 'app' from '/home/codex/schofield/app/__init__.py'>
comp = 'security', import_path = 'app.security'

    def _dot_lookup(thing, comp, import_path):
        try:
            return getattr(thing, comp)
        except AttributeError:
>           __import__(import_path)
E           ModuleNotFoundError: No module named 'app.security'

/usr/lib/python3.10/unittest/mock.py:1250: ModuleNotFoundError
_________________ test_7_3_2_10_halt_on_unsupported_data_type __________________

thing = <module 'app' from '/home/codex/schofield/app/__init__.py'>
comp = 'validation', import_path = 'app.validation'

    def _dot_lookup(thing, comp, import_path):
        try:
>           return getattr(thing, comp)
E           AttributeError: module 'app' has no attribute 'validation'

/usr/lib/python3.10/unittest/mock.py:1248: AttributeError

During handling of the above exception, another exception occurred:

mocker = <pytest_mock.plugin.MockerFixture object at 0x7ff0bceedd20>

    def test_7_3_2_10_halt_on_unsupported_data_type(mocker):
        """Verifies 7.3.2.10 — Halt on unsupported data type at validation (E5)."""
>       validate = mocker.patch("app.validation.rows.Validator.validate", create=True, side_effect=RuntimeError("unsupported type"))

tests/functional/test_epic_a_data_model_functional.py:1581: 
_ _ _ _ _ _ _ _ _ _ _ _ _ _ _ _ _ _ _ _ _ _ _ _ _ _ _ _ _ _ _ _ _ _ _ _ _ _ _ _ 
../.local/lib/python3.10/site-packages/pytest_mock/plugin.py:439: in __call__
    return self._start_patch(
../.local/lib/python3.10/site-packages/pytest_mock/plugin.py:257: in _start_patch
    mocked: MockType = p.start()
/usr/lib/python3.10/unittest/mock.py:1595: in start
    result = self.__enter__()
/usr/lib/python3.10/unittest/mock.py:1431: in __enter__
    self.target = self.getter()
/usr/lib/python3.10/unittest/mock.py:1618: in <lambda>
    getter = lambda: _importer(target)
/usr/lib/python3.10/unittest/mock.py:1261: in _importer
    thing = _dot_lookup(thing, comp, import_path)
_ _ _ _ _ _ _ _ _ _ _ _ _ _ _ _ _ _ _ _ _ _ _ _ _ _ _ _ _ _ _ _ _ _ _ _ _ _ _ _ 

thing = <module 'app' from '/home/codex/schofield/app/__init__.py'>
comp = 'validation', import_path = 'app.validation'

    def _dot_lookup(thing, comp, import_path):
        try:
            return getattr(thing, comp)
        except AttributeError:
>           __import__(import_path)
E           ModuleNotFoundError: No module named 'app.validation'

/usr/lib/python3.10/unittest/mock.py:1250: ModuleNotFoundError
_________________ test_7_3_2_11_halt_on_out_of_order_migration _________________

mocker = <pytest_mock.plugin.MockerFixture object at 0x7ff0bcd94610>

    def test_7_3_2_11_halt_on_out_of_order_migration(mocker):
        """Verifies 7.3.2.11 — Halt on out-of-order migration execution (E1/E2/E8)."""
>       enforce = mocker.patch("app.db.migrations_runner.MigrationRunner.enforce_order", create=True, side_effect=RuntimeError("out of order"))

tests/functional/test_epic_a_data_model_functional.py:1594: 
_ _ _ _ _ _ _ _ _ _ _ _ _ _ _ _ _ _ _ _ _ _ _ _ _ _ _ _ _ _ _ _ _ _ _ _ _ _ _ _ 
../.local/lib/python3.10/site-packages/pytest_mock/plugin.py:439: in __call__
    return self._start_patch(
../.local/lib/python3.10/site-packages/pytest_mock/plugin.py:257: in _start_patch
    mocked: MockType = p.start()
/usr/lib/python3.10/unittest/mock.py:1595: in start
    result = self.__enter__()
/usr/lib/python3.10/unittest/mock.py:1431: in __enter__
    self.target = self.getter()
/usr/lib/python3.10/unittest/mock.py:1618: in <lambda>
    getter = lambda: _importer(target)
/usr/lib/python3.10/unittest/mock.py:1261: in _importer
    thing = _dot_lookup(thing, comp, import_path)
_ _ _ _ _ _ _ _ _ _ _ _ _ _ _ _ _ _ _ _ _ _ _ _ _ _ _ _ _ _ _ _ _ _ _ _ _ _ _ _ 

thing = <module 'app.db.migrations_runner' from '/home/codex/schofield/app/db/migrations_runner.py'>
comp = 'MigrationRunner'
import_path = 'app.db.migrations_runner.MigrationRunner'

    def _dot_lookup(thing, comp, import_path):
        try:
            return getattr(thing, comp)
        except AttributeError:
>           __import__(import_path)
E           ModuleNotFoundError: No module named 'app.db.migrations_runner.MigrationRunner'; 'app.db.migrations_runner' is not a package

/usr/lib/python3.10/unittest/mock.py:1250: ModuleNotFoundError
_______________ test_7_3_2_12_halt_on_unidentified_runtime_error _______________

thing = <module 'app' from '/home/codex/schofield/app/__init__.py'>
comp = 'telemetry', import_path = 'app.telemetry'

    def _dot_lookup(thing, comp, import_path):
        try:
>           return getattr(thing, comp)
E           AttributeError: module 'app' has no attribute 'telemetry'

/usr/lib/python3.10/unittest/mock.py:1248: AttributeError

During handling of the above exception, another exception occurred:

mocker = <pytest_mock.plugin.MockerFixture object at 0x7ff0bde334f0>

    def test_7_3_2_12_halt_on_unidentified_runtime_error(mocker):
        """Verifies 7.3.2.12 — Halt on unidentified runtime error (catch-all)."""
        # Simulate telemetry emission on catch-all
>       emit = mocker.patch("app.telemetry.emit_error", create=True)

tests/functional/test_epic_a_data_model_functional.py:1608: 
_ _ _ _ _ _ _ _ _ _ _ _ _ _ _ _ _ _ _ _ _ _ _ _ _ _ _ _ _ _ _ _ _ _ _ _ _ _ _ _ 
../.local/lib/python3.10/site-packages/pytest_mock/plugin.py:439: in __call__
    return self._start_patch(
../.local/lib/python3.10/site-packages/pytest_mock/plugin.py:257: in _start_patch
    mocked: MockType = p.start()
/usr/lib/python3.10/unittest/mock.py:1595: in start
    result = self.__enter__()
/usr/lib/python3.10/unittest/mock.py:1431: in __enter__
    self.target = self.getter()
/usr/lib/python3.10/unittest/mock.py:1618: in <lambda>
    getter = lambda: _importer(target)
/usr/lib/python3.10/unittest/mock.py:1261: in _importer
    thing = _dot_lookup(thing, comp, import_path)
_ _ _ _ _ _ _ _ _ _ _ _ _ _ _ _ _ _ _ _ _ _ _ _ _ _ _ _ _ _ _ _ _ _ _ _ _ _ _ _ 

thing = <module 'app' from '/home/codex/schofield/app/__init__.py'>
comp = 'telemetry', import_path = 'app.telemetry'

    def _dot_lookup(thing, comp, import_path):
        try:
            return getattr(thing, comp)
        except AttributeError:
>           __import__(import_path)
E           ModuleNotFoundError: No module named 'app.telemetry'

/usr/lib/python3.10/unittest/mock.py:1250: ModuleNotFoundError
______________ test_7_3_2_13_db_connectivity_failure_halting_step ______________

mocker = <pytest_mock.plugin.MockerFixture object at 0x7ff0bcd94070>

    def test_7_3_2_13_db_connectivity_failure_halting_step(mocker):
        """Verifies 7.3.2.13 — Database connectivity failure halts STEP-3 and prevents downstream operations."""
>       connect = mocker.patch("app.db.base.DB.connect", create=True, side_effect=RuntimeError("network unreachable"))

tests/functional/test_epic_a_data_model_functional.py:1624: 
_ _ _ _ _ _ _ _ _ _ _ _ _ _ _ _ _ _ _ _ _ _ _ _ _ _ _ _ _ _ _ _ _ _ _ _ _ _ _ _ 
../.local/lib/python3.10/site-packages/pytest_mock/plugin.py:439: in __call__
    return self._start_patch(
../.local/lib/python3.10/site-packages/pytest_mock/plugin.py:257: in _start_patch
    mocked: MockType = p.start()
/usr/lib/python3.10/unittest/mock.py:1595: in start
    result = self.__enter__()
/usr/lib/python3.10/unittest/mock.py:1431: in __enter__
    self.target = self.getter()
/usr/lib/python3.10/unittest/mock.py:1618: in <lambda>
    getter = lambda: _importer(target)
/usr/lib/python3.10/unittest/mock.py:1261: in _importer
    thing = _dot_lookup(thing, comp, import_path)
_ _ _ _ _ _ _ _ _ _ _ _ _ _ _ _ _ _ _ _ _ _ _ _ _ _ _ _ _ _ _ _ _ _ _ _ _ _ _ _ 

thing = <module 'app.db.base' from '/home/codex/schofield/app/db/base.py'>
comp = 'DB', import_path = 'app.db.base.DB'

    def _dot_lookup(thing, comp, import_path):
        try:
            return getattr(thing, comp)
        except AttributeError:
>           __import__(import_path)
E           ModuleNotFoundError: No module named 'app.db.base.DB'; 'app.db.base' is not a package

/usr/lib/python3.10/unittest/mock.py:1250: ModuleNotFoundError
_________ test_7_3_2_14_db_permission_failure_prevents_schema_creation _________

mocker = <pytest_mock.plugin.MockerFixture object at 0x7ff0bce9ba00>

    def test_7_3_2_14_db_permission_failure_prevents_schema_creation(mocker):
        """Verifies 7.3.2.14 — Database permission failure halts STEP-3 and prevents schema creation."""
>       ddl = mocker.patch("app.db.base.DB.execute_ddl", create=True, side_effect=RuntimeError("permission denied"))

tests/functional/test_epic_a_data_model_functional.py:1636: 
_ _ _ _ _ _ _ _ _ _ _ _ _ _ _ _ _ _ _ _ _ _ _ _ _ _ _ _ _ _ _ _ _ _ _ _ _ _ _ _ 
../.local/lib/python3.10/site-packages/pytest_mock/plugin.py:439: in __call__
    return self._start_patch(
../.local/lib/python3.10/site-packages/pytest_mock/plugin.py:257: in _start_patch
    mocked: MockType = p.start()
/usr/lib/python3.10/unittest/mock.py:1595: in start
    result = self.__enter__()
/usr/lib/python3.10/unittest/mock.py:1431: in __enter__
    self.target = self.getter()
/usr/lib/python3.10/unittest/mock.py:1618: in <lambda>
    getter = lambda: _importer(target)
/usr/lib/python3.10/unittest/mock.py:1261: in _importer
    thing = _dot_lookup(thing, comp, import_path)
_ _ _ _ _ _ _ _ _ _ _ _ _ _ _ _ _ _ _ _ _ _ _ _ _ _ _ _ _ _ _ _ _ _ _ _ _ _ _ _ 

thing = <module 'app.db.base' from '/home/codex/schofield/app/db/base.py'>
comp = 'DB', import_path = 'app.db.base.DB'

    def _dot_lookup(thing, comp, import_path):
        try:
            return getattr(thing, comp)
        except AttributeError:
>           __import__(import_path)
E           ModuleNotFoundError: No module named 'app.db.base.DB'; 'app.db.base' is not a package

/usr/lib/python3.10/unittest/mock.py:1250: ModuleNotFoundError
_____________ test_7_3_2_15_tls_handshake_failure_prevents_inserts _____________

mocker = <pytest_mock.plugin.MockerFixture object at 0x7ff0bcebfc10>

    def test_7_3_2_15_tls_handshake_failure_prevents_inserts(mocker):
        """Verifies 7.3.2.15 — TLS certificate/handshake failure prevents inserts."""
>       handshake = mocker.patch("app.db.base.DB.connect_tls", create=True, side_effect=RuntimeError("handshake failed"))

tests/functional/test_epic_a_data_model_functional.py:1648: 
_ _ _ _ _ _ _ _ _ _ _ _ _ _ _ _ _ _ _ _ _ _ _ _ _ _ _ _ _ _ _ _ _ _ _ _ _ _ _ _ 
../.local/lib/python3.10/site-packages/pytest_mock/plugin.py:439: in __call__
    return self._start_patch(
../.local/lib/python3.10/site-packages/pytest_mock/plugin.py:257: in _start_patch
    mocked: MockType = p.start()
/usr/lib/python3.10/unittest/mock.py:1595: in start
    result = self.__enter__()
/usr/lib/python3.10/unittest/mock.py:1431: in __enter__
    self.target = self.getter()
/usr/lib/python3.10/unittest/mock.py:1618: in <lambda>
    getter = lambda: _importer(target)
/usr/lib/python3.10/unittest/mock.py:1261: in _importer
    thing = _dot_lookup(thing, comp, import_path)
_ _ _ _ _ _ _ _ _ _ _ _ _ _ _ _ _ _ _ _ _ _ _ _ _ _ _ _ _ _ _ _ _ _ _ _ _ _ _ _ 

thing = <module 'app.db.base' from '/home/codex/schofield/app/db/base.py'>
comp = 'DB', import_path = 'app.db.base.DB'

    def _dot_lookup(thing, comp, import_path):
        try:
            return getattr(thing, comp)
        except AttributeError:
>           __import__(import_path)
E           ModuleNotFoundError: No module named 'app.db.base.DB'; 'app.db.base' is not a package

/usr/lib/python3.10/unittest/mock.py:1250: ModuleNotFoundError
_________ test_7_3_2_16_db_storage_exhaustion_prevents_journal_updates _________

mocker = <pytest_mock.plugin.MockerFixture object at 0x7ff0bdda5300>

    def test_7_3_2_16_db_storage_exhaustion_prevents_journal_updates(mocker):
        """Verifies 7.3.2.16 — Database storage exhaustion halts STEP-3 and prevents journal updates."""
>       create_table = mocker.patch("app.db.base.DB.execute_ddl", create=True, side_effect=RuntimeError("no space left on device"))

tests/functional/test_epic_a_data_model_functional.py:1660: 
_ _ _ _ _ _ _ _ _ _ _ _ _ _ _ _ _ _ _ _ _ _ _ _ _ _ _ _ _ _ _ _ _ _ _ _ _ _ _ _ 
../.local/lib/python3.10/site-packages/pytest_mock/plugin.py:439: in __call__
    return self._start_patch(
../.local/lib/python3.10/site-packages/pytest_mock/plugin.py:257: in _start_patch
    mocked: MockType = p.start()
/usr/lib/python3.10/unittest/mock.py:1595: in start
    result = self.__enter__()
/usr/lib/python3.10/unittest/mock.py:1431: in __enter__
    self.target = self.getter()
/usr/lib/python3.10/unittest/mock.py:1618: in <lambda>
    getter = lambda: _importer(target)
/usr/lib/python3.10/unittest/mock.py:1261: in _importer
    thing = _dot_lookup(thing, comp, import_path)
_ _ _ _ _ _ _ _ _ _ _ _ _ _ _ _ _ _ _ _ _ _ _ _ _ _ _ _ _ _ _ _ _ _ _ _ _ _ _ _ 

thing = <module 'app.db.base' from '/home/codex/schofield/app/db/base.py'>
comp = 'DB', import_path = 'app.db.base.DB'

    def _dot_lookup(thing, comp, import_path):
        try:
            return getattr(thing, comp)
        except AttributeError:
>           __import__(import_path)
E           ModuleNotFoundError: No module named 'app.db.base.DB'; 'app.db.base' is not a package

/usr/lib/python3.10/unittest/mock.py:1250: ModuleNotFoundError
_________ test_7_3_2_17_temp_fs_unavailable_prevents_step_continuation _________

thing = <module 'app' from '/home/codex/schofield/app/__init__.py'>, comp = 'fs'
import_path = 'app.fs'

    def _dot_lookup(thing, comp, import_path):
        try:
>           return getattr(thing, comp)
E           AttributeError: module 'app' has no attribute 'fs'

/usr/lib/python3.10/unittest/mock.py:1248: AttributeError

During handling of the above exception, another exception occurred:

mocker = <pytest_mock.plugin.MockerFixture object at 0x7ff0bcd78430>

    def test_7_3_2_17_temp_fs_unavailable_prevents_step_continuation(mocker):
        """Verifies 7.3.2.17 — Filesystem/temp unavailability prevents STEP-3 continuation (degraded stop)."""
>       temp = mocker.patch("app.fs.tmp.allocate", create=True, side_effect=RuntimeError("temp unavailable"))

tests/functional/test_epic_a_data_model_functional.py:1672: 
_ _ _ _ _ _ _ _ _ _ _ _ _ _ _ _ _ _ _ _ _ _ _ _ _ _ _ _ _ _ _ _ _ _ _ _ _ _ _ _ 
../.local/lib/python3.10/site-packages/pytest_mock/plugin.py:439: in __call__
    return self._start_patch(
../.local/lib/python3.10/site-packages/pytest_mock/plugin.py:257: in _start_patch
    mocked: MockType = p.start()
/usr/lib/python3.10/unittest/mock.py:1595: in start
    result = self.__enter__()
/usr/lib/python3.10/unittest/mock.py:1431: in __enter__
    self.target = self.getter()
/usr/lib/python3.10/unittest/mock.py:1618: in <lambda>
    getter = lambda: _importer(target)
/usr/lib/python3.10/unittest/mock.py:1261: in _importer
    thing = _dot_lookup(thing, comp, import_path)
_ _ _ _ _ _ _ _ _ _ _ _ _ _ _ _ _ _ _ _ _ _ _ _ _ _ _ _ _ _ _ _ _ _ _ _ _ _ _ _ 

thing = <module 'app' from '/home/codex/schofield/app/__init__.py'>, comp = 'fs'
import_path = 'app.fs'

    def _dot_lookup(thing, comp, import_path):
        try:
            return getattr(thing, comp)
        except AttributeError:
>           __import__(import_path)
E           ModuleNotFoundError: No module named 'app.fs'

/usr/lib/python3.10/unittest/mock.py:1250: ModuleNotFoundError
______________ test_7_3_2_18_kms_unavailability_halts_encryption _______________

thing = <module 'app' from '/home/codex/schofield/app/__init__.py'>
comp = 'encryption', import_path = 'app.encryption'

    def _dot_lookup(thing, comp, import_path):
        try:
>           return getattr(thing, comp)
E           AttributeError: module 'app' has no attribute 'encryption'

/usr/lib/python3.10/unittest/mock.py:1248: AttributeError

During handling of the above exception, another exception occurred:

mocker = <pytest_mock.plugin.MockerFixture object at 0x7ff0be03c1f0>

    def test_7_3_2_18_kms_unavailability_halts_encryption(mocker):
        """Verifies 7.3.2.18 — KMS unavailability halts STEP-3 encryption operations and prevents access."""
>       get_key = mocker.patch("app.encryption.kms.get_key", create=True, side_effect=RuntimeError("kms down"))

tests/functional/test_epic_a_data_model_functional.py:1684: 
_ _ _ _ _ _ _ _ _ _ _ _ _ _ _ _ _ _ _ _ _ _ _ _ _ _ _ _ _ _ _ _ _ _ _ _ _ _ _ _ 
../.local/lib/python3.10/site-packages/pytest_mock/plugin.py:439: in __call__
    return self._start_patch(
../.local/lib/python3.10/site-packages/pytest_mock/plugin.py:257: in _start_patch
    mocked: MockType = p.start()
/usr/lib/python3.10/unittest/mock.py:1595: in start
    result = self.__enter__()
/usr/lib/python3.10/unittest/mock.py:1431: in __enter__
    self.target = self.getter()
/usr/lib/python3.10/unittest/mock.py:1618: in <lambda>
    getter = lambda: _importer(target)
/usr/lib/python3.10/unittest/mock.py:1261: in _importer
    thing = _dot_lookup(thing, comp, import_path)
_ _ _ _ _ _ _ _ _ _ _ _ _ _ _ _ _ _ _ _ _ _ _ _ _ _ _ _ _ _ _ _ _ _ _ _ _ _ _ _ 

thing = <module 'app' from '/home/codex/schofield/app/__init__.py'>
comp = 'encryption', import_path = 'app.encryption'

    def _dot_lookup(thing, comp, import_path):
        try:
            return getattr(thing, comp)
        except AttributeError:
>           __import__(import_path)
E           ModuleNotFoundError: No module named 'app.encryption'

/usr/lib/python3.10/unittest/mock.py:1250: ModuleNotFoundError
__________________ test_7_3_2_19_time_sync_failure_halts_step __________________

thing = <module 'app' from '/home/codex/schofield/app/__init__.py'>
comp = 'time', import_path = 'app.time'

    def _dot_lookup(thing, comp, import_path):
        try:
>           return getattr(thing, comp)
E           AttributeError: module 'app' has no attribute 'time'

/usr/lib/python3.10/unittest/mock.py:1248: AttributeError

During handling of the above exception, another exception occurred:

mocker = <pytest_mock.plugin.MockerFixture object at 0x7ff0bde1e4a0>

    def test_7_3_2_19_time_sync_failure_halts_step(mocker):
        """Verifies 7.3.2.19 — Time synchronisation failure halts STEP-3 where timestamps are required."""
>       time_sync = mocker.patch("app.time.sync.ensure_synchronised", create=True, side_effect=RuntimeError("time skew"))

tests/functional/test_epic_a_data_model_functional.py:1696: 
_ _ _ _ _ _ _ _ _ _ _ _ _ _ _ _ _ _ _ _ _ _ _ _ _ _ _ _ _ _ _ _ _ _ _ _ _ _ _ _ 
../.local/lib/python3.10/site-packages/pytest_mock/plugin.py:439: in __call__
    return self._start_patch(
../.local/lib/python3.10/site-packages/pytest_mock/plugin.py:257: in _start_patch
    mocked: MockType = p.start()
/usr/lib/python3.10/unittest/mock.py:1595: in start
    result = self.__enter__()
/usr/lib/python3.10/unittest/mock.py:1431: in __enter__
    self.target = self.getter()
/usr/lib/python3.10/unittest/mock.py:1618: in <lambda>
    getter = lambda: _importer(target)
/usr/lib/python3.10/unittest/mock.py:1261: in _importer
    thing = _dot_lookup(thing, comp, import_path)
_ _ _ _ _ _ _ _ _ _ _ _ _ _ _ _ _ _ _ _ _ _ _ _ _ _ _ _ _ _ _ _ _ _ _ _ _ _ _ _ 

thing = <module 'app' from '/home/codex/schofield/app/__init__.py'>
comp = 'time', import_path = 'app.time'

    def _dot_lookup(thing, comp, import_path):
        try:
            return getattr(thing, comp)
        except AttributeError:
>           __import__(import_path)
E           ModuleNotFoundError: No module named 'app.time'

/usr/lib/python3.10/unittest/mock.py:1250: ModuleNotFoundError
__________ test_7_3_2_20_config_dependency_unavailable_prevents_start __________

mocker = <pytest_mock.plugin.MockerFixture object at 0x7ff0bccf8850>

    def test_7_3_2_20_config_dependency_unavailable_prevents_start(mocker):
        """Verifies 7.3.2.20 — Configuration dependency unavailability prevents STEP-3 initiation."""
>       cfg = mocker.patch("app.config.loader.load", create=True, side_effect=RuntimeError("config unavailable"))

tests/functional/test_epic_a_data_model_functional.py:1708: 
_ _ _ _ _ _ _ _ _ _ _ _ _ _ _ _ _ _ _ _ _ _ _ _ _ _ _ _ _ _ _ _ _ _ _ _ _ _ _ _ 
../.local/lib/python3.10/site-packages/pytest_mock/plugin.py:439: in __call__
    return self._start_patch(
../.local/lib/python3.10/site-packages/pytest_mock/plugin.py:257: in _start_patch
    mocked: MockType = p.start()
/usr/lib/python3.10/unittest/mock.py:1595: in start
    result = self.__enter__()
/usr/lib/python3.10/unittest/mock.py:1431: in __enter__
    self.target = self.getter()
/usr/lib/python3.10/unittest/mock.py:1618: in <lambda>
    getter = lambda: _importer(target)
/usr/lib/python3.10/unittest/mock.py:1261: in _importer
    thing = _dot_lookup(thing, comp, import_path)
_ _ _ _ _ _ _ _ _ _ _ _ _ _ _ _ _ _ _ _ _ _ _ _ _ _ _ _ _ _ _ _ _ _ _ _ _ _ _ _ 

thing = <module 'app.config' from '/home/codex/schofield/app/config.py'>
comp = 'loader', import_path = 'app.config.loader'

    def _dot_lookup(thing, comp, import_path):
        try:
            return getattr(thing, comp)
        except AttributeError:
>           __import__(import_path)
E           ModuleNotFoundError: No module named 'app.config.loader'; 'app.config' is not a package

/usr/lib/python3.10/unittest/mock.py:1250: ModuleNotFoundError
____________________ test_7_2_2_22_enhanced_error_semantics ____________________

mocker = <pytest_mock.plugin.MockerFixture object at 0x7ff0bde2afe0>

    def _t(mocker) -> None:
        # Apply boundary patch
>       mocked = mocker.patch(_cfg["patch"], create=True)

tests/functional/test_epic_a_data_model_functional.py:1774: 
_ _ _ _ _ _ _ _ _ _ _ _ _ _ _ _ _ _ _ _ _ _ _ _ _ _ _ _ _ _ _ _ _ _ _ _ _ _ _ _ 
../.local/lib/python3.10/site-packages/pytest_mock/plugin.py:439: in __call__
    return self._start_patch(
../.local/lib/python3.10/site-packages/pytest_mock/plugin.py:257: in _start_patch
    mocked: MockType = p.start()
/usr/lib/python3.10/unittest/mock.py:1595: in start
    result = self.__enter__()
/usr/lib/python3.10/unittest/mock.py:1431: in __enter__
    self.target = self.getter()
/usr/lib/python3.10/unittest/mock.py:1618: in <lambda>
    getter = lambda: _importer(target)
/usr/lib/python3.10/unittest/mock.py:1261: in _importer
    thing = _dot_lookup(thing, comp, import_path)
_ _ _ _ _ _ _ _ _ _ _ _ _ _ _ _ _ _ _ _ _ _ _ _ _ _ _ _ _ _ _ _ _ _ _ _ _ _ _ _ 

thing = <module 'app.db.base' from '/home/codex/schofield/app/db/base.py'>
comp = 'DB', import_path = 'app.db.base.DB'

    def _dot_lookup(thing, comp, import_path):
        try:
            return getattr(thing, comp)
        except AttributeError:
>           __import__(import_path)
E           ModuleNotFoundError: No module named 'app.db.base.DB'; 'app.db.base' is not a package

/usr/lib/python3.10/unittest/mock.py:1250: ModuleNotFoundError
____________________ test_7_2_2_23_enhanced_error_semantics ____________________

mocker = <pytest_mock.plugin.MockerFixture object at 0x7ff0bce8f880>

    def _t(mocker) -> None:
        # Apply boundary patch
>       mocked = mocker.patch(_cfg["patch"], create=True)

tests/functional/test_epic_a_data_model_functional.py:1774: 
_ _ _ _ _ _ _ _ _ _ _ _ _ _ _ _ _ _ _ _ _ _ _ _ _ _ _ _ _ _ _ _ _ _ _ _ _ _ _ _ 
../.local/lib/python3.10/site-packages/pytest_mock/plugin.py:439: in __call__
    return self._start_patch(
../.local/lib/python3.10/site-packages/pytest_mock/plugin.py:257: in _start_patch
    mocked: MockType = p.start()
/usr/lib/python3.10/unittest/mock.py:1595: in start
    result = self.__enter__()
/usr/lib/python3.10/unittest/mock.py:1431: in __enter__
    self.target = self.getter()
/usr/lib/python3.10/unittest/mock.py:1618: in <lambda>
    getter = lambda: _importer(target)
/usr/lib/python3.10/unittest/mock.py:1261: in _importer
    thing = _dot_lookup(thing, comp, import_path)
_ _ _ _ _ _ _ _ _ _ _ _ _ _ _ _ _ _ _ _ _ _ _ _ _ _ _ _ _ _ _ _ _ _ _ _ _ _ _ _ 

thing = <module 'app.db.base' from '/home/codex/schofield/app/db/base.py'>
comp = 'DB', import_path = 'app.db.base.DB'

    def _dot_lookup(thing, comp, import_path):
        try:
            return getattr(thing, comp)
        except AttributeError:
>           __import__(import_path)
E           ModuleNotFoundError: No module named 'app.db.base.DB'; 'app.db.base' is not a package

/usr/lib/python3.10/unittest/mock.py:1250: ModuleNotFoundError
____________________ test_7_2_2_24_enhanced_error_semantics ____________________

thing = <module 'app' from '/home/codex/schofield/app/__init__.py'>
comp = 'net', import_path = 'app.net'

    def _dot_lookup(thing, comp, import_path):
        try:
>           return getattr(thing, comp)
E           AttributeError: module 'app' has no attribute 'net'

/usr/lib/python3.10/unittest/mock.py:1248: AttributeError

During handling of the above exception, another exception occurred:

mocker = <pytest_mock.plugin.MockerFixture object at 0x7ff0bde2a980>

    def _t(mocker) -> None:
        # Apply boundary patch
>       mocked = mocker.patch(_cfg["patch"], create=True)

tests/functional/test_epic_a_data_model_functional.py:1774: 
_ _ _ _ _ _ _ _ _ _ _ _ _ _ _ _ _ _ _ _ _ _ _ _ _ _ _ _ _ _ _ _ _ _ _ _ _ _ _ _ 
../.local/lib/python3.10/site-packages/pytest_mock/plugin.py:439: in __call__
    return self._start_patch(
../.local/lib/python3.10/site-packages/pytest_mock/plugin.py:257: in _start_patch
    mocked: MockType = p.start()
/usr/lib/python3.10/unittest/mock.py:1595: in start
    result = self.__enter__()
/usr/lib/python3.10/unittest/mock.py:1431: in __enter__
    self.target = self.getter()
/usr/lib/python3.10/unittest/mock.py:1618: in <lambda>
    getter = lambda: _importer(target)
/usr/lib/python3.10/unittest/mock.py:1261: in _importer
    thing = _dot_lookup(thing, comp, import_path)
_ _ _ _ _ _ _ _ _ _ _ _ _ _ _ _ _ _ _ _ _ _ _ _ _ _ _ _ _ _ _ _ _ _ _ _ _ _ _ _ 

thing = <module 'app' from '/home/codex/schofield/app/__init__.py'>
comp = 'net', import_path = 'app.net'

    def _dot_lookup(thing, comp, import_path):
        try:
            return getattr(thing, comp)
        except AttributeError:
>           __import__(import_path)
E           ModuleNotFoundError: No module named 'app.net'

/usr/lib/python3.10/unittest/mock.py:1250: ModuleNotFoundError
____________________ test_7_2_2_25_enhanced_error_semantics ____________________

mocker = <pytest_mock.plugin.MockerFixture object at 0x7ff0bcd6a830>

    def _t(mocker) -> None:
        # Apply boundary patch
>       mocked = mocker.patch(_cfg["patch"], create=True)

tests/functional/test_epic_a_data_model_functional.py:1774: 
_ _ _ _ _ _ _ _ _ _ _ _ _ _ _ _ _ _ _ _ _ _ _ _ _ _ _ _ _ _ _ _ _ _ _ _ _ _ _ _ 
../.local/lib/python3.10/site-packages/pytest_mock/plugin.py:439: in __call__
    return self._start_patch(
../.local/lib/python3.10/site-packages/pytest_mock/plugin.py:257: in _start_patch
    mocked: MockType = p.start()
/usr/lib/python3.10/unittest/mock.py:1595: in start
    result = self.__enter__()
/usr/lib/python3.10/unittest/mock.py:1431: in __enter__
    self.target = self.getter()
/usr/lib/python3.10/unittest/mock.py:1618: in <lambda>
    getter = lambda: _importer(target)
/usr/lib/python3.10/unittest/mock.py:1261: in _importer
    thing = _dot_lookup(thing, comp, import_path)
_ _ _ _ _ _ _ _ _ _ _ _ _ _ _ _ _ _ _ _ _ _ _ _ _ _ _ _ _ _ _ _ _ _ _ _ _ _ _ _ 

thing = <module 'app.db.base' from '/home/codex/schofield/app/db/base.py'>
comp = 'DB', import_path = 'app.db.base.DB'

    def _dot_lookup(thing, comp, import_path):
        try:
            return getattr(thing, comp)
        except AttributeError:
>           __import__(import_path)
E           ModuleNotFoundError: No module named 'app.db.base.DB'; 'app.db.base' is not a package

/usr/lib/python3.10/unittest/mock.py:1250: ModuleNotFoundError
____________________ test_7_2_2_26_enhanced_error_semantics ____________________

mocker = <pytest_mock.plugin.MockerFixture object at 0x7ff0bcfbf4f0>

    def _t(mocker) -> None:
        # Apply boundary patch
>       mocked = mocker.patch(_cfg["patch"], create=True)

tests/functional/test_epic_a_data_model_functional.py:1774: 
_ _ _ _ _ _ _ _ _ _ _ _ _ _ _ _ _ _ _ _ _ _ _ _ _ _ _ _ _ _ _ _ _ _ _ _ _ _ _ _ 
../.local/lib/python3.10/site-packages/pytest_mock/plugin.py:439: in __call__
    return self._start_patch(
../.local/lib/python3.10/site-packages/pytest_mock/plugin.py:257: in _start_patch
    mocked: MockType = p.start()
/usr/lib/python3.10/unittest/mock.py:1595: in start
    result = self.__enter__()
/usr/lib/python3.10/unittest/mock.py:1431: in __enter__
    self.target = self.getter()
/usr/lib/python3.10/unittest/mock.py:1618: in <lambda>
    getter = lambda: _importer(target)
/usr/lib/python3.10/unittest/mock.py:1261: in _importer
    thing = _dot_lookup(thing, comp, import_path)
_ _ _ _ _ _ _ _ _ _ _ _ _ _ _ _ _ _ _ _ _ _ _ _ _ _ _ _ _ _ _ _ _ _ _ _ _ _ _ _ 

thing = <module 'app.db.base' from '/home/codex/schofield/app/db/base.py'>
comp = 'DB', import_path = 'app.db.base.DB'

    def _dot_lookup(thing, comp, import_path):
        try:
            return getattr(thing, comp)
        except AttributeError:
>           __import__(import_path)
E           ModuleNotFoundError: No module named 'app.db.base.DB'; 'app.db.base' is not a package

/usr/lib/python3.10/unittest/mock.py:1250: ModuleNotFoundError
____________________ test_7_2_2_27_enhanced_error_semantics ____________________

mocker = <pytest_mock.plugin.MockerFixture object at 0x7ff0bcd69690>

    def _t(mocker) -> None:
        # Apply boundary patch
>       mocked = mocker.patch(_cfg["patch"], create=True)

tests/functional/test_epic_a_data_model_functional.py:1774: 
_ _ _ _ _ _ _ _ _ _ _ _ _ _ _ _ _ _ _ _ _ _ _ _ _ _ _ _ _ _ _ _ _ _ _ _ _ _ _ _ 
../.local/lib/python3.10/site-packages/pytest_mock/plugin.py:439: in __call__
    return self._start_patch(
../.local/lib/python3.10/site-packages/pytest_mock/plugin.py:257: in _start_patch
    mocked: MockType = p.start()
/usr/lib/python3.10/unittest/mock.py:1595: in start
    result = self.__enter__()
/usr/lib/python3.10/unittest/mock.py:1431: in __enter__
    self.target = self.getter()
/usr/lib/python3.10/unittest/mock.py:1618: in <lambda>
    getter = lambda: _importer(target)
/usr/lib/python3.10/unittest/mock.py:1261: in _importer
    thing = _dot_lookup(thing, comp, import_path)
_ _ _ _ _ _ _ _ _ _ _ _ _ _ _ _ _ _ _ _ _ _ _ _ _ _ _ _ _ _ _ _ _ _ _ _ _ _ _ _ 

thing = <module 'app.db.base' from '/home/codex/schofield/app/db/base.py'>
comp = 'DB', import_path = 'app.db.base.DB'

    def _dot_lookup(thing, comp, import_path):
        try:
            return getattr(thing, comp)
        except AttributeError:
>           __import__(import_path)
E           ModuleNotFoundError: No module named 'app.db.base.DB'; 'app.db.base' is not a package

/usr/lib/python3.10/unittest/mock.py:1250: ModuleNotFoundError
____________________ test_7_2_2_28_enhanced_error_semantics ____________________

mocker = <pytest_mock.plugin.MockerFixture object at 0x7ff0bcdb71f0>

    def _t(mocker) -> None:
        # Apply boundary patch
>       mocked = mocker.patch(_cfg["patch"], create=True)

tests/functional/test_epic_a_data_model_functional.py:1774: 
_ _ _ _ _ _ _ _ _ _ _ _ _ _ _ _ _ _ _ _ _ _ _ _ _ _ _ _ _ _ _ _ _ _ _ _ _ _ _ _ 
../.local/lib/python3.10/site-packages/pytest_mock/plugin.py:439: in __call__
    return self._start_patch(
../.local/lib/python3.10/site-packages/pytest_mock/plugin.py:257: in _start_patch
    mocked: MockType = p.start()
/usr/lib/python3.10/unittest/mock.py:1595: in start
    result = self.__enter__()
/usr/lib/python3.10/unittest/mock.py:1431: in __enter__
    self.target = self.getter()
/usr/lib/python3.10/unittest/mock.py:1618: in <lambda>
    getter = lambda: _importer(target)
/usr/lib/python3.10/unittest/mock.py:1261: in _importer
    thing = _dot_lookup(thing, comp, import_path)
_ _ _ _ _ _ _ _ _ _ _ _ _ _ _ _ _ _ _ _ _ _ _ _ _ _ _ _ _ _ _ _ _ _ _ _ _ _ _ _ 

thing = <module 'app.db.migrations_runner' from '/home/codex/schofield/app/db/migrations_runner.py'>
comp = 'MigrationRunner'
import_path = 'app.db.migrations_runner.MigrationRunner'

    def _dot_lookup(thing, comp, import_path):
        try:
            return getattr(thing, comp)
        except AttributeError:
>           __import__(import_path)
E           ModuleNotFoundError: No module named 'app.db.migrations_runner.MigrationRunner'; 'app.db.migrations_runner' is not a package

/usr/lib/python3.10/unittest/mock.py:1250: ModuleNotFoundError
____________________ test_7_2_2_29_enhanced_error_semantics ____________________

thing = <module 'app' from '/home/codex/schofield/app/__init__.py'>
comp = 'encryption', import_path = 'app.encryption'

    def _dot_lookup(thing, comp, import_path):
        try:
>           return getattr(thing, comp)
E           AttributeError: module 'app' has no attribute 'encryption'

/usr/lib/python3.10/unittest/mock.py:1248: AttributeError

During handling of the above exception, another exception occurred:

mocker = <pytest_mock.plugin.MockerFixture object at 0x7ff0bcd2ee30>

    def _t(mocker) -> None:
        # Apply boundary patch
>       mocked = mocker.patch(_cfg["patch"], create=True)

tests/functional/test_epic_a_data_model_functional.py:1774: 
_ _ _ _ _ _ _ _ _ _ _ _ _ _ _ _ _ _ _ _ _ _ _ _ _ _ _ _ _ _ _ _ _ _ _ _ _ _ _ _ 
../.local/lib/python3.10/site-packages/pytest_mock/plugin.py:439: in __call__
    return self._start_patch(
../.local/lib/python3.10/site-packages/pytest_mock/plugin.py:257: in _start_patch
    mocked: MockType = p.start()
/usr/lib/python3.10/unittest/mock.py:1595: in start
    result = self.__enter__()
/usr/lib/python3.10/unittest/mock.py:1431: in __enter__
    self.target = self.getter()
/usr/lib/python3.10/unittest/mock.py:1618: in <lambda>
    getter = lambda: _importer(target)
/usr/lib/python3.10/unittest/mock.py:1261: in _importer
    thing = _dot_lookup(thing, comp, import_path)
_ _ _ _ _ _ _ _ _ _ _ _ _ _ _ _ _ _ _ _ _ _ _ _ _ _ _ _ _ _ _ _ _ _ _ _ _ _ _ _ 

thing = <module 'app' from '/home/codex/schofield/app/__init__.py'>
comp = 'encryption', import_path = 'app.encryption'

    def _dot_lookup(thing, comp, import_path):
        try:
            return getattr(thing, comp)
        except AttributeError:
>           __import__(import_path)
E           ModuleNotFoundError: No module named 'app.encryption'

/usr/lib/python3.10/unittest/mock.py:1250: ModuleNotFoundError
____________________ test_7_2_2_30_enhanced_error_semantics ____________________

thing = <module 'app' from '/home/codex/schofield/app/__init__.py'>
comp = 'encryption', import_path = 'app.encryption'

    def _dot_lookup(thing, comp, import_path):
        try:
>           return getattr(thing, comp)
E           AttributeError: module 'app' has no attribute 'encryption'

/usr/lib/python3.10/unittest/mock.py:1248: AttributeError

During handling of the above exception, another exception occurred:

mocker = <pytest_mock.plugin.MockerFixture object at 0x7ff0bcdb56c0>

    def _t(mocker) -> None:
        # Apply boundary patch
>       mocked = mocker.patch(_cfg["patch"], create=True)

tests/functional/test_epic_a_data_model_functional.py:1774: 
_ _ _ _ _ _ _ _ _ _ _ _ _ _ _ _ _ _ _ _ _ _ _ _ _ _ _ _ _ _ _ _ _ _ _ _ _ _ _ _ 
../.local/lib/python3.10/site-packages/pytest_mock/plugin.py:439: in __call__
    return self._start_patch(
../.local/lib/python3.10/site-packages/pytest_mock/plugin.py:257: in _start_patch
    mocked: MockType = p.start()
/usr/lib/python3.10/unittest/mock.py:1595: in start
    result = self.__enter__()
/usr/lib/python3.10/unittest/mock.py:1431: in __enter__
    self.target = self.getter()
/usr/lib/python3.10/unittest/mock.py:1618: in <lambda>
    getter = lambda: _importer(target)
/usr/lib/python3.10/unittest/mock.py:1261: in _importer
    thing = _dot_lookup(thing, comp, import_path)
_ _ _ _ _ _ _ _ _ _ _ _ _ _ _ _ _ _ _ _ _ _ _ _ _ _ _ _ _ _ _ _ _ _ _ _ _ _ _ _ 

thing = <module 'app' from '/home/codex/schofield/app/__init__.py'>
comp = 'encryption', import_path = 'app.encryption'

    def _dot_lookup(thing, comp, import_path):
        try:
            return getattr(thing, comp)
        except AttributeError:
>           __import__(import_path)
E           ModuleNotFoundError: No module named 'app.encryption'

/usr/lib/python3.10/unittest/mock.py:1250: ModuleNotFoundError
____________________ test_7_2_2_31_enhanced_error_semantics ____________________

thing = <module 'app' from '/home/codex/schofield/app/__init__.py'>
comp = 'encryption', import_path = 'app.encryption'

    def _dot_lookup(thing, comp, import_path):
        try:
>           return getattr(thing, comp)
E           AttributeError: module 'app' has no attribute 'encryption'

/usr/lib/python3.10/unittest/mock.py:1248: AttributeError

During handling of the above exception, another exception occurred:

mocker = <pytest_mock.plugin.MockerFixture object at 0x7ff0bcf82500>

    def _t(mocker) -> None:
        # Apply boundary patch
>       mocked = mocker.patch(_cfg["patch"], create=True)

tests/functional/test_epic_a_data_model_functional.py:1774: 
_ _ _ _ _ _ _ _ _ _ _ _ _ _ _ _ _ _ _ _ _ _ _ _ _ _ _ _ _ _ _ _ _ _ _ _ _ _ _ _ 
../.local/lib/python3.10/site-packages/pytest_mock/plugin.py:439: in __call__
    return self._start_patch(
../.local/lib/python3.10/site-packages/pytest_mock/plugin.py:257: in _start_patch
    mocked: MockType = p.start()
/usr/lib/python3.10/unittest/mock.py:1595: in start
    result = self.__enter__()
/usr/lib/python3.10/unittest/mock.py:1431: in __enter__
    self.target = self.getter()
/usr/lib/python3.10/unittest/mock.py:1618: in <lambda>
    getter = lambda: _importer(target)
/usr/lib/python3.10/unittest/mock.py:1261: in _importer
    thing = _dot_lookup(thing, comp, import_path)
_ _ _ _ _ _ _ _ _ _ _ _ _ _ _ _ _ _ _ _ _ _ _ _ _ _ _ _ _ _ _ _ _ _ _ _ _ _ _ _ 

thing = <module 'app' from '/home/codex/schofield/app/__init__.py'>
comp = 'encryption', import_path = 'app.encryption'

    def _dot_lookup(thing, comp, import_path):
        try:
            return getattr(thing, comp)
        except AttributeError:
>           __import__(import_path)
E           ModuleNotFoundError: No module named 'app.encryption'

/usr/lib/python3.10/unittest/mock.py:1250: ModuleNotFoundError
____________________ test_7_2_2_32_enhanced_error_semantics ____________________

thing = <module 'app' from '/home/codex/schofield/app/__init__.py'>
comp = 'encryption', import_path = 'app.encryption'

    def _dot_lookup(thing, comp, import_path):
        try:
>           return getattr(thing, comp)
E           AttributeError: module 'app' has no attribute 'encryption'

/usr/lib/python3.10/unittest/mock.py:1248: AttributeError

During handling of the above exception, another exception occurred:

mocker = <pytest_mock.plugin.MockerFixture object at 0x7ff0bccfa3e0>

    def _t(mocker) -> None:
        # Apply boundary patch
>       mocked = mocker.patch(_cfg["patch"], create=True)

tests/functional/test_epic_a_data_model_functional.py:1774: 
_ _ _ _ _ _ _ _ _ _ _ _ _ _ _ _ _ _ _ _ _ _ _ _ _ _ _ _ _ _ _ _ _ _ _ _ _ _ _ _ 
../.local/lib/python3.10/site-packages/pytest_mock/plugin.py:439: in __call__
    return self._start_patch(
../.local/lib/python3.10/site-packages/pytest_mock/plugin.py:257: in _start_patch
    mocked: MockType = p.start()
/usr/lib/python3.10/unittest/mock.py:1595: in start
    result = self.__enter__()
/usr/lib/python3.10/unittest/mock.py:1431: in __enter__
    self.target = self.getter()
/usr/lib/python3.10/unittest/mock.py:1618: in <lambda>
    getter = lambda: _importer(target)
/usr/lib/python3.10/unittest/mock.py:1261: in _importer
    thing = _dot_lookup(thing, comp, import_path)
_ _ _ _ _ _ _ _ _ _ _ _ _ _ _ _ _ _ _ _ _ _ _ _ _ _ _ _ _ _ _ _ _ _ _ _ _ _ _ _ 

thing = <module 'app' from '/home/codex/schofield/app/__init__.py'>
comp = 'encryption', import_path = 'app.encryption'

    def _dot_lookup(thing, comp, import_path):
        try:
            return getattr(thing, comp)
        except AttributeError:
>           __import__(import_path)
E           ModuleNotFoundError: No module named 'app.encryption'

/usr/lib/python3.10/unittest/mock.py:1250: ModuleNotFoundError
____________________ test_7_2_2_33_enhanced_error_semantics ____________________

thing = <module 'app' from '/home/codex/schofield/app/__init__.py'>
comp = 'encryption', import_path = 'app.encryption'

    def _dot_lookup(thing, comp, import_path):
        try:
>           return getattr(thing, comp)
E           AttributeError: module 'app' has no attribute 'encryption'

/usr/lib/python3.10/unittest/mock.py:1248: AttributeError

During handling of the above exception, another exception occurred:

mocker = <pytest_mock.plugin.MockerFixture object at 0x7ff0bdda5510>

    def _t(mocker) -> None:
        # Apply boundary patch
>       mocked = mocker.patch(_cfg["patch"], create=True)

tests/functional/test_epic_a_data_model_functional.py:1774: 
_ _ _ _ _ _ _ _ _ _ _ _ _ _ _ _ _ _ _ _ _ _ _ _ _ _ _ _ _ _ _ _ _ _ _ _ _ _ _ _ 
../.local/lib/python3.10/site-packages/pytest_mock/plugin.py:439: in __call__
    return self._start_patch(
../.local/lib/python3.10/site-packages/pytest_mock/plugin.py:257: in _start_patch
    mocked: MockType = p.start()
/usr/lib/python3.10/unittest/mock.py:1595: in start
    result = self.__enter__()
/usr/lib/python3.10/unittest/mock.py:1431: in __enter__
    self.target = self.getter()
/usr/lib/python3.10/unittest/mock.py:1618: in <lambda>
    getter = lambda: _importer(target)
/usr/lib/python3.10/unittest/mock.py:1261: in _importer
    thing = _dot_lookup(thing, comp, import_path)
_ _ _ _ _ _ _ _ _ _ _ _ _ _ _ _ _ _ _ _ _ _ _ _ _ _ _ _ _ _ _ _ _ _ _ _ _ _ _ _ 

thing = <module 'app' from '/home/codex/schofield/app/__init__.py'>
comp = 'encryption', import_path = 'app.encryption'

    def _dot_lookup(thing, comp, import_path):
        try:
            return getattr(thing, comp)
        except AttributeError:
>           __import__(import_path)
E           ModuleNotFoundError: No module named 'app.encryption'

/usr/lib/python3.10/unittest/mock.py:1250: ModuleNotFoundError
____________________ test_7_2_2_34_enhanced_error_semantics ____________________

thing = <module 'app' from '/home/codex/schofield/app/__init__.py'>
comp = 'cache', import_path = 'app.cache'

    def _dot_lookup(thing, comp, import_path):
        try:
>           return getattr(thing, comp)
E           AttributeError: module 'app' has no attribute 'cache'

/usr/lib/python3.10/unittest/mock.py:1248: AttributeError

During handling of the above exception, another exception occurred:

mocker = <pytest_mock.plugin.MockerFixture object at 0x7ff0bccf8970>

    def _t(mocker) -> None:
        # Apply boundary patch
>       mocked = mocker.patch(_cfg["patch"], create=True)

tests/functional/test_epic_a_data_model_functional.py:1774: 
_ _ _ _ _ _ _ _ _ _ _ _ _ _ _ _ _ _ _ _ _ _ _ _ _ _ _ _ _ _ _ _ _ _ _ _ _ _ _ _ 
../.local/lib/python3.10/site-packages/pytest_mock/plugin.py:439: in __call__
    return self._start_patch(
../.local/lib/python3.10/site-packages/pytest_mock/plugin.py:257: in _start_patch
    mocked: MockType = p.start()
/usr/lib/python3.10/unittest/mock.py:1595: in start
    result = self.__enter__()
/usr/lib/python3.10/unittest/mock.py:1431: in __enter__
    self.target = self.getter()
/usr/lib/python3.10/unittest/mock.py:1618: in <lambda>
    getter = lambda: _importer(target)
/usr/lib/python3.10/unittest/mock.py:1261: in _importer
    thing = _dot_lookup(thing, comp, import_path)
_ _ _ _ _ _ _ _ _ _ _ _ _ _ _ _ _ _ _ _ _ _ _ _ _ _ _ _ _ _ _ _ _ _ _ _ _ _ _ _ 

thing = <module 'app' from '/home/codex/schofield/app/__init__.py'>
comp = 'cache', import_path = 'app.cache'

    def _dot_lookup(thing, comp, import_path):
        try:
            return getattr(thing, comp)
        except AttributeError:
>           __import__(import_path)
E           ModuleNotFoundError: No module named 'app.cache'

/usr/lib/python3.10/unittest/mock.py:1250: ModuleNotFoundError
____________________ test_7_2_2_35_enhanced_error_semantics ____________________

thing = <module 'app' from '/home/codex/schofield/app/__init__.py'>
comp = 'secrets', import_path = 'app.secrets'

    def _dot_lookup(thing, comp, import_path):
        try:
>           return getattr(thing, comp)
E           AttributeError: module 'app' has no attribute 'secrets'

/usr/lib/python3.10/unittest/mock.py:1248: AttributeError

During handling of the above exception, another exception occurred:

mocker = <pytest_mock.plugin.MockerFixture object at 0x7ff0bceeed40>

    def _t(mocker) -> None:
        # Apply boundary patch
>       mocked = mocker.patch(_cfg["patch"], create=True)

tests/functional/test_epic_a_data_model_functional.py:1774: 
_ _ _ _ _ _ _ _ _ _ _ _ _ _ _ _ _ _ _ _ _ _ _ _ _ _ _ _ _ _ _ _ _ _ _ _ _ _ _ _ 
../.local/lib/python3.10/site-packages/pytest_mock/plugin.py:439: in __call__
    return self._start_patch(
../.local/lib/python3.10/site-packages/pytest_mock/plugin.py:257: in _start_patch
    mocked: MockType = p.start()
/usr/lib/python3.10/unittest/mock.py:1595: in start
    result = self.__enter__()
/usr/lib/python3.10/unittest/mock.py:1431: in __enter__
    self.target = self.getter()
/usr/lib/python3.10/unittest/mock.py:1618: in <lambda>
    getter = lambda: _importer(target)
/usr/lib/python3.10/unittest/mock.py:1261: in _importer
    thing = _dot_lookup(thing, comp, import_path)
_ _ _ _ _ _ _ _ _ _ _ _ _ _ _ _ _ _ _ _ _ _ _ _ _ _ _ _ _ _ _ _ _ _ _ _ _ _ _ _ 

thing = <module 'app' from '/home/codex/schofield/app/__init__.py'>
comp = 'secrets', import_path = 'app.secrets'

    def _dot_lookup(thing, comp, import_path):
        try:
            return getattr(thing, comp)
        except AttributeError:
>           __import__(import_path)
E           ModuleNotFoundError: No module named 'app.secrets'

/usr/lib/python3.10/unittest/mock.py:1250: ModuleNotFoundError
____________________ test_7_2_2_36_enhanced_error_semantics ____________________

mocker = <pytest_mock.plugin.MockerFixture object at 0x7ff0bcfc5480>

    def _t(mocker) -> None:
        # Apply boundary patch
>       mocked = mocker.patch(_cfg["patch"], create=True)

tests/functional/test_epic_a_data_model_functional.py:1774: 
_ _ _ _ _ _ _ _ _ _ _ _ _ _ _ _ _ _ _ _ _ _ _ _ _ _ _ _ _ _ _ _ _ _ _ _ _ _ _ _ 
../.local/lib/python3.10/site-packages/pytest_mock/plugin.py:439: in __call__
    return self._start_patch(
../.local/lib/python3.10/site-packages/pytest_mock/plugin.py:257: in _start_patch
    mocked: MockType = p.start()
/usr/lib/python3.10/unittest/mock.py:1595: in start
    result = self.__enter__()
/usr/lib/python3.10/unittest/mock.py:1431: in __enter__
    self.target = self.getter()
/usr/lib/python3.10/unittest/mock.py:1618: in <lambda>
    getter = lambda: _importer(target)
/usr/lib/python3.10/unittest/mock.py:1261: in _importer
    thing = _dot_lookup(thing, comp, import_path)
_ _ _ _ _ _ _ _ _ _ _ _ _ _ _ _ _ _ _ _ _ _ _ _ _ _ _ _ _ _ _ _ _ _ _ _ _ _ _ _ 

thing = <module 'app.db.base' from '/home/codex/schofield/app/db/base.py'>
comp = 'DB', import_path = 'app.db.base.DB'

    def _dot_lookup(thing, comp, import_path):
        try:
            return getattr(thing, comp)
        except AttributeError:
>           __import__(import_path)
E           ModuleNotFoundError: No module named 'app.db.base.DB'; 'app.db.base' is not a package

/usr/lib/python3.10/unittest/mock.py:1250: ModuleNotFoundError
____________________ test_7_2_2_37_enhanced_error_semantics ____________________

thing = <module 'app' from '/home/codex/schofield/app/__init__.py'>
comp = 'logging', import_path = 'app.logging'

    def _dot_lookup(thing, comp, import_path):
        try:
>           return getattr(thing, comp)
E           AttributeError: module 'app' has no attribute 'logging'

/usr/lib/python3.10/unittest/mock.py:1248: AttributeError

During handling of the above exception, another exception occurred:

mocker = <pytest_mock.plugin.MockerFixture object at 0x7ff0bceeffa0>

    def _t(mocker) -> None:
        # Apply boundary patch
>       mocked = mocker.patch(_cfg["patch"], create=True)

tests/functional/test_epic_a_data_model_functional.py:1774: 
_ _ _ _ _ _ _ _ _ _ _ _ _ _ _ _ _ _ _ _ _ _ _ _ _ _ _ _ _ _ _ _ _ _ _ _ _ _ _ _ 
../.local/lib/python3.10/site-packages/pytest_mock/plugin.py:439: in __call__
    return self._start_patch(
../.local/lib/python3.10/site-packages/pytest_mock/plugin.py:257: in _start_patch
    mocked: MockType = p.start()
/usr/lib/python3.10/unittest/mock.py:1595: in start
    result = self.__enter__()
/usr/lib/python3.10/unittest/mock.py:1431: in __enter__
    self.target = self.getter()
/usr/lib/python3.10/unittest/mock.py:1618: in <lambda>
    getter = lambda: _importer(target)
/usr/lib/python3.10/unittest/mock.py:1261: in _importer
    thing = _dot_lookup(thing, comp, import_path)
_ _ _ _ _ _ _ _ _ _ _ _ _ _ _ _ _ _ _ _ _ _ _ _ _ _ _ _ _ _ _ _ _ _ _ _ _ _ _ _ 

thing = <module 'app' from '/home/codex/schofield/app/__init__.py'>
comp = 'logging', import_path = 'app.logging'

    def _dot_lookup(thing, comp, import_path):
        try:
            return getattr(thing, comp)
        except AttributeError:
>           __import__(import_path)
E           ModuleNotFoundError: No module named 'app.logging'

/usr/lib/python3.10/unittest/mock.py:1250: ModuleNotFoundError
____________________ test_7_2_2_38_enhanced_error_semantics ____________________

mocker = <pytest_mock.plugin.MockerFixture object at 0x7ff0bce8fca0>

    def _t(mocker) -> None:
        # Apply boundary patch
>       mocked = mocker.patch(_cfg["patch"], create=True)

tests/functional/test_epic_a_data_model_functional.py:1774: 
_ _ _ _ _ _ _ _ _ _ _ _ _ _ _ _ _ _ _ _ _ _ _ _ _ _ _ _ _ _ _ _ _ _ _ _ _ _ _ _ 
../.local/lib/python3.10/site-packages/pytest_mock/plugin.py:439: in __call__
    return self._start_patch(
../.local/lib/python3.10/site-packages/pytest_mock/plugin.py:257: in _start_patch
    mocked: MockType = p.start()
/usr/lib/python3.10/unittest/mock.py:1595: in start
    result = self.__enter__()
/usr/lib/python3.10/unittest/mock.py:1431: in __enter__
    self.target = self.getter()
/usr/lib/python3.10/unittest/mock.py:1618: in <lambda>
    getter = lambda: _importer(target)
/usr/lib/python3.10/unittest/mock.py:1261: in _importer
    thing = _dot_lookup(thing, comp, import_path)
_ _ _ _ _ _ _ _ _ _ _ _ _ _ _ _ _ _ _ _ _ _ _ _ _ _ _ _ _ _ _ _ _ _ _ _ _ _ _ _ 

thing = <module 'app.db.base' from '/home/codex/schofield/app/db/base.py'>
comp = 'DB', import_path = 'app.db.base.DB'

    def _dot_lookup(thing, comp, import_path):
        try:
            return getattr(thing, comp)
        except AttributeError:
>           __import__(import_path)
E           ModuleNotFoundError: No module named 'app.db.base.DB'; 'app.db.base' is not a package

/usr/lib/python3.10/unittest/mock.py:1250: ModuleNotFoundError
____________________ test_7_2_2_39_enhanced_error_semantics ____________________

mocker = <pytest_mock.plugin.MockerFixture object at 0x7ff0bde1f5e0>

    def _t(mocker) -> None:
        # Apply boundary patch
>       mocked = mocker.patch(_cfg["patch"], create=True)

tests/functional/test_epic_a_data_model_functional.py:1774: 
_ _ _ _ _ _ _ _ _ _ _ _ _ _ _ _ _ _ _ _ _ _ _ _ _ _ _ _ _ _ _ _ _ _ _ _ _ _ _ _ 
../.local/lib/python3.10/site-packages/pytest_mock/plugin.py:439: in __call__
    return self._start_patch(
../.local/lib/python3.10/site-packages/pytest_mock/plugin.py:257: in _start_patch
    mocked: MockType = p.start()
/usr/lib/python3.10/unittest/mock.py:1595: in start
    result = self.__enter__()
/usr/lib/python3.10/unittest/mock.py:1431: in __enter__
    self.target = self.getter()
/usr/lib/python3.10/unittest/mock.py:1618: in <lambda>
    getter = lambda: _importer(target)
/usr/lib/python3.10/unittest/mock.py:1261: in _importer
    thing = _dot_lookup(thing, comp, import_path)
_ _ _ _ _ _ _ _ _ _ _ _ _ _ _ _ _ _ _ _ _ _ _ _ _ _ _ _ _ _ _ _ _ _ _ _ _ _ _ _ 

thing = <module 'app.db.base' from '/home/codex/schofield/app/db/base.py'>
comp = 'DB', import_path = 'app.db.base.DB'

    def _dot_lookup(thing, comp, import_path):
        try:
            return getattr(thing, comp)
        except AttributeError:
>           __import__(import_path)
E           ModuleNotFoundError: No module named 'app.db.base.DB'; 'app.db.base' is not a package

/usr/lib/python3.10/unittest/mock.py:1250: ModuleNotFoundError
____________________ test_7_2_2_40_enhanced_error_semantics ____________________

mocker = <pytest_mock.plugin.MockerFixture object at 0x7ff0bcef6050>

    def _t(mocker) -> None:
        # Apply boundary patch
>       mocked = mocker.patch(_cfg["patch"], create=True)

tests/functional/test_epic_a_data_model_functional.py:1774: 
_ _ _ _ _ _ _ _ _ _ _ _ _ _ _ _ _ _ _ _ _ _ _ _ _ _ _ _ _ _ _ _ _ _ _ _ _ _ _ _ 
../.local/lib/python3.10/site-packages/pytest_mock/plugin.py:439: in __call__
    return self._start_patch(
../.local/lib/python3.10/site-packages/pytest_mock/plugin.py:257: in _start_patch
    mocked: MockType = p.start()
/usr/lib/python3.10/unittest/mock.py:1595: in start
    result = self.__enter__()
/usr/lib/python3.10/unittest/mock.py:1431: in __enter__
    self.target = self.getter()
/usr/lib/python3.10/unittest/mock.py:1618: in <lambda>
    getter = lambda: _importer(target)
/usr/lib/python3.10/unittest/mock.py:1261: in _importer
    thing = _dot_lookup(thing, comp, import_path)
_ _ _ _ _ _ _ _ _ _ _ _ _ _ _ _ _ _ _ _ _ _ _ _ _ _ _ _ _ _ _ _ _ _ _ _ _ _ _ _ 

thing = <module 'app.db.base' from '/home/codex/schofield/app/db/base.py'>
comp = 'DB', import_path = 'app.db.base.DB'

    def _dot_lookup(thing, comp, import_path):
        try:
            return getattr(thing, comp)
        except AttributeError:
>           __import__(import_path)
E           ModuleNotFoundError: No module named 'app.db.base.DB'; 'app.db.base' is not a package

/usr/lib/python3.10/unittest/mock.py:1250: ModuleNotFoundError
____________________ test_7_2_2_41_enhanced_error_semantics ____________________

mocker = <pytest_mock.plugin.MockerFixture object at 0x7ff0bce8f5b0>

    def _t(mocker) -> None:
        # Apply boundary patch
>       mocked = mocker.patch(_cfg["patch"], create=True)

tests/functional/test_epic_a_data_model_functional.py:1774: 
_ _ _ _ _ _ _ _ _ _ _ _ _ _ _ _ _ _ _ _ _ _ _ _ _ _ _ _ _ _ _ _ _ _ _ _ _ _ _ _ 
../.local/lib/python3.10/site-packages/pytest_mock/plugin.py:439: in __call__
    return self._start_patch(
../.local/lib/python3.10/site-packages/pytest_mock/plugin.py:257: in _start_patch
    mocked: MockType = p.start()
/usr/lib/python3.10/unittest/mock.py:1595: in start
    result = self.__enter__()
/usr/lib/python3.10/unittest/mock.py:1431: in __enter__
    self.target = self.getter()
/usr/lib/python3.10/unittest/mock.py:1618: in <lambda>
    getter = lambda: _importer(target)
/usr/lib/python3.10/unittest/mock.py:1261: in _importer
    thing = _dot_lookup(thing, comp, import_path)
_ _ _ _ _ _ _ _ _ _ _ _ _ _ _ _ _ _ _ _ _ _ _ _ _ _ _ _ _ _ _ _ _ _ _ _ _ _ _ _ 

thing = <module 'app.db.migrations_runner' from '/home/codex/schofield/app/db/migrations_runner.py'>
comp = 'MigrationRunner'
import_path = 'app.db.migrations_runner.MigrationRunner'

    def _dot_lookup(thing, comp, import_path):
        try:
            return getattr(thing, comp)
        except AttributeError:
>           __import__(import_path)
E           ModuleNotFoundError: No module named 'app.db.migrations_runner.MigrationRunner'; 'app.db.migrations_runner' is not a package

/usr/lib/python3.10/unittest/mock.py:1250: ModuleNotFoundError
____________________ test_7_2_2_42_enhanced_error_semantics ____________________

mocker = <pytest_mock.plugin.MockerFixture object at 0x7ff0bd054f40>

    def _t(mocker) -> None:
        # Apply boundary patch
>       mocked = mocker.patch(_cfg["patch"], create=True)

tests/functional/test_epic_a_data_model_functional.py:1774: 
_ _ _ _ _ _ _ _ _ _ _ _ _ _ _ _ _ _ _ _ _ _ _ _ _ _ _ _ _ _ _ _ _ _ _ _ _ _ _ _ 
../.local/lib/python3.10/site-packages/pytest_mock/plugin.py:439: in __call__
    return self._start_patch(
../.local/lib/python3.10/site-packages/pytest_mock/plugin.py:257: in _start_patch
    mocked: MockType = p.start()
/usr/lib/python3.10/unittest/mock.py:1595: in start
    result = self.__enter__()
/usr/lib/python3.10/unittest/mock.py:1431: in __enter__
    self.target = self.getter()
/usr/lib/python3.10/unittest/mock.py:1618: in <lambda>
    getter = lambda: _importer(target)
/usr/lib/python3.10/unittest/mock.py:1261: in _importer
    thing = _dot_lookup(thing, comp, import_path)
_ _ _ _ _ _ _ _ _ _ _ _ _ _ _ _ _ _ _ _ _ _ _ _ _ _ _ _ _ _ _ _ _ _ _ _ _ _ _ _ 

thing = <module 'app.db.migrations_runner' from '/home/codex/schofield/app/db/migrations_runner.py'>
comp = 'MigrationRunner'
import_path = 'app.db.migrations_runner.MigrationRunner'

    def _dot_lookup(thing, comp, import_path):
        try:
            return getattr(thing, comp)
        except AttributeError:
>           __import__(import_path)
E           ModuleNotFoundError: No module named 'app.db.migrations_runner.MigrationRunner'; 'app.db.migrations_runner' is not a package

/usr/lib/python3.10/unittest/mock.py:1250: ModuleNotFoundError
____________________ test_7_2_2_43_enhanced_error_semantics ____________________

mocker = <pytest_mock.plugin.MockerFixture object at 0x7ff0bcebd750>

    def _t(mocker) -> None:
        # Apply boundary patch
>       mocked = mocker.patch(_cfg["patch"], create=True)

tests/functional/test_epic_a_data_model_functional.py:1774: 
_ _ _ _ _ _ _ _ _ _ _ _ _ _ _ _ _ _ _ _ _ _ _ _ _ _ _ _ _ _ _ _ _ _ _ _ _ _ _ _ 
../.local/lib/python3.10/site-packages/pytest_mock/plugin.py:439: in __call__
    return self._start_patch(
../.local/lib/python3.10/site-packages/pytest_mock/plugin.py:257: in _start_patch
    mocked: MockType = p.start()
/usr/lib/python3.10/unittest/mock.py:1595: in start
    result = self.__enter__()
/usr/lib/python3.10/unittest/mock.py:1431: in __enter__
    self.target = self.getter()
/usr/lib/python3.10/unittest/mock.py:1618: in <lambda>
    getter = lambda: _importer(target)
/usr/lib/python3.10/unittest/mock.py:1261: in _importer
    thing = _dot_lookup(thing, comp, import_path)
_ _ _ _ _ _ _ _ _ _ _ _ _ _ _ _ _ _ _ _ _ _ _ _ _ _ _ _ _ _ _ _ _ _ _ _ _ _ _ _ 

thing = <module 'app.db.migrations_runner' from '/home/codex/schofield/app/db/migrations_runner.py'>
comp = 'MigrationRunner'
import_path = 'app.db.migrations_runner.MigrationRunner'

    def _dot_lookup(thing, comp, import_path):
        try:
            return getattr(thing, comp)
        except AttributeError:
>           __import__(import_path)
E           ModuleNotFoundError: No module named 'app.db.migrations_runner.MigrationRunner'; 'app.db.migrations_runner' is not a package

/usr/lib/python3.10/unittest/mock.py:1250: ModuleNotFoundError
____________________ test_7_2_2_44_enhanced_error_semantics ____________________

mocker = <pytest_mock.plugin.MockerFixture object at 0x7ff0bce8faf0>

    def _t(mocker) -> None:
        # Apply boundary patch
>       mocked = mocker.patch(_cfg["patch"], create=True)

tests/functional/test_epic_a_data_model_functional.py:1774: 
_ _ _ _ _ _ _ _ _ _ _ _ _ _ _ _ _ _ _ _ _ _ _ _ _ _ _ _ _ _ _ _ _ _ _ _ _ _ _ _ 
../.local/lib/python3.10/site-packages/pytest_mock/plugin.py:439: in __call__
    return self._start_patch(
../.local/lib/python3.10/site-packages/pytest_mock/plugin.py:257: in _start_patch
    mocked: MockType = p.start()
/usr/lib/python3.10/unittest/mock.py:1595: in start
    result = self.__enter__()
/usr/lib/python3.10/unittest/mock.py:1431: in __enter__
    self.target = self.getter()
/usr/lib/python3.10/unittest/mock.py:1618: in <lambda>
    getter = lambda: _importer(target)
/usr/lib/python3.10/unittest/mock.py:1261: in _importer
    thing = _dot_lookup(thing, comp, import_path)
_ _ _ _ _ _ _ _ _ _ _ _ _ _ _ _ _ _ _ _ _ _ _ _ _ _ _ _ _ _ _ _ _ _ _ _ _ _ _ _ 

thing = <module 'app.db.migrations_runner' from '/home/codex/schofield/app/db/migrations_runner.py'>
comp = 'MigrationRunner'
import_path = 'app.db.migrations_runner.MigrationRunner'

    def _dot_lookup(thing, comp, import_path):
        try:
            return getattr(thing, comp)
        except AttributeError:
>           __import__(import_path)
E           ModuleNotFoundError: No module named 'app.db.migrations_runner.MigrationRunner'; 'app.db.migrations_runner' is not a package

/usr/lib/python3.10/unittest/mock.py:1250: ModuleNotFoundError
____________________ test_7_2_2_45_enhanced_error_semantics ____________________

mocker = <pytest_mock.plugin.MockerFixture object at 0x7ff0bcdb5690>

    def _t(mocker) -> None:
        # Apply boundary patch
>       mocked = mocker.patch(_cfg["patch"], create=True)

tests/functional/test_epic_a_data_model_functional.py:1774: 
_ _ _ _ _ _ _ _ _ _ _ _ _ _ _ _ _ _ _ _ _ _ _ _ _ _ _ _ _ _ _ _ _ _ _ _ _ _ _ _ 
../.local/lib/python3.10/site-packages/pytest_mock/plugin.py:439: in __call__
    return self._start_patch(
../.local/lib/python3.10/site-packages/pytest_mock/plugin.py:257: in _start_patch
    mocked: MockType = p.start()
/usr/lib/python3.10/unittest/mock.py:1595: in start
    result = self.__enter__()
/usr/lib/python3.10/unittest/mock.py:1431: in __enter__
    self.target = self.getter()
/usr/lib/python3.10/unittest/mock.py:1618: in <lambda>
    getter = lambda: _importer(target)
/usr/lib/python3.10/unittest/mock.py:1261: in _importer
    thing = _dot_lookup(thing, comp, import_path)
_ _ _ _ _ _ _ _ _ _ _ _ _ _ _ _ _ _ _ _ _ _ _ _ _ _ _ _ _ _ _ _ _ _ _ _ _ _ _ _ 

thing = <module 'app.db.migrations_runner' from '/home/codex/schofield/app/db/migrations_runner.py'>
comp = 'MigrationRunner'
import_path = 'app.db.migrations_runner.MigrationRunner'

    def _dot_lookup(thing, comp, import_path):
        try:
            return getattr(thing, comp)
        except AttributeError:
>           __import__(import_path)
E           ModuleNotFoundError: No module named 'app.db.migrations_runner.MigrationRunner'; 'app.db.migrations_runner' is not a package

/usr/lib/python3.10/unittest/mock.py:1250: ModuleNotFoundError
____________________ test_7_2_2_46_enhanced_error_semantics ____________________

mocker = <pytest_mock.plugin.MockerFixture object at 0x7ff0bcd6bfa0>

    def _t(mocker) -> None:
        # Apply boundary patch
>       mocked = mocker.patch(_cfg["patch"], create=True)

tests/functional/test_epic_a_data_model_functional.py:1774: 
_ _ _ _ _ _ _ _ _ _ _ _ _ _ _ _ _ _ _ _ _ _ _ _ _ _ _ _ _ _ _ _ _ _ _ _ _ _ _ _ 
../.local/lib/python3.10/site-packages/pytest_mock/plugin.py:439: in __call__
    return self._start_patch(
../.local/lib/python3.10/site-packages/pytest_mock/plugin.py:257: in _start_patch
    mocked: MockType = p.start()
/usr/lib/python3.10/unittest/mock.py:1595: in start
    result = self.__enter__()
/usr/lib/python3.10/unittest/mock.py:1431: in __enter__
    self.target = self.getter()
/usr/lib/python3.10/unittest/mock.py:1618: in <lambda>
    getter = lambda: _importer(target)
/usr/lib/python3.10/unittest/mock.py:1261: in _importer
    thing = _dot_lookup(thing, comp, import_path)
_ _ _ _ _ _ _ _ _ _ _ _ _ _ _ _ _ _ _ _ _ _ _ _ _ _ _ _ _ _ _ _ _ _ _ _ _ _ _ _ 

thing = <module 'app.db.migrations_runner' from '/home/codex/schofield/app/db/migrations_runner.py'>
comp = 'MigrationRunner'
import_path = 'app.db.migrations_runner.MigrationRunner'

    def _dot_lookup(thing, comp, import_path):
        try:
            return getattr(thing, comp)
        except AttributeError:
>           __import__(import_path)
E           ModuleNotFoundError: No module named 'app.db.migrations_runner.MigrationRunner'; 'app.db.migrations_runner' is not a package

/usr/lib/python3.10/unittest/mock.py:1250: ModuleNotFoundError
____________________ test_7_2_2_47_enhanced_error_semantics ____________________

mocker = <pytest_mock.plugin.MockerFixture object at 0x7ff0bdde50f0>

    def _t(mocker) -> None:
        # Apply boundary patch
>       mocked = mocker.patch(_cfg["patch"], create=True)

tests/functional/test_epic_a_data_model_functional.py:1774: 
_ _ _ _ _ _ _ _ _ _ _ _ _ _ _ _ _ _ _ _ _ _ _ _ _ _ _ _ _ _ _ _ _ _ _ _ _ _ _ _ 
../.local/lib/python3.10/site-packages/pytest_mock/plugin.py:439: in __call__
    return self._start_patch(
../.local/lib/python3.10/site-packages/pytest_mock/plugin.py:257: in _start_patch
    mocked: MockType = p.start()
/usr/lib/python3.10/unittest/mock.py:1595: in start
    result = self.__enter__()
/usr/lib/python3.10/unittest/mock.py:1431: in __enter__
    self.target = self.getter()
/usr/lib/python3.10/unittest/mock.py:1618: in <lambda>
    getter = lambda: _importer(target)
/usr/lib/python3.10/unittest/mock.py:1261: in _importer
    thing = _dot_lookup(thing, comp, import_path)
_ _ _ _ _ _ _ _ _ _ _ _ _ _ _ _ _ _ _ _ _ _ _ _ _ _ _ _ _ _ _ _ _ _ _ _ _ _ _ _ 

thing = <module 'app.db.migrations_runner' from '/home/codex/schofield/app/db/migrations_runner.py'>
comp = 'MigrationRunner'
import_path = 'app.db.migrations_runner.MigrationRunner'

    def _dot_lookup(thing, comp, import_path):
        try:
            return getattr(thing, comp)
        except AttributeError:
>           __import__(import_path)
E           ModuleNotFoundError: No module named 'app.db.migrations_runner.MigrationRunner'; 'app.db.migrations_runner' is not a package

/usr/lib/python3.10/unittest/mock.py:1250: ModuleNotFoundError
____________________ test_7_2_2_48_enhanced_error_semantics ____________________

mocker = <pytest_mock.plugin.MockerFixture object at 0x7ff0bcf6f9d0>

    def _t(mocker) -> None:
        # Apply boundary patch
>       mocked = mocker.patch(_cfg["patch"], create=True)

tests/functional/test_epic_a_data_model_functional.py:1774: 
_ _ _ _ _ _ _ _ _ _ _ _ _ _ _ _ _ _ _ _ _ _ _ _ _ _ _ _ _ _ _ _ _ _ _ _ _ _ _ _ 
../.local/lib/python3.10/site-packages/pytest_mock/plugin.py:439: in __call__
    return self._start_patch(
../.local/lib/python3.10/site-packages/pytest_mock/plugin.py:257: in _start_patch
    mocked: MockType = p.start()
/usr/lib/python3.10/unittest/mock.py:1595: in start
    result = self.__enter__()
/usr/lib/python3.10/unittest/mock.py:1431: in __enter__
    self.target = self.getter()
/usr/lib/python3.10/unittest/mock.py:1618: in <lambda>
    getter = lambda: _importer(target)
/usr/lib/python3.10/unittest/mock.py:1261: in _importer
    thing = _dot_lookup(thing, comp, import_path)
_ _ _ _ _ _ _ _ _ _ _ _ _ _ _ _ _ _ _ _ _ _ _ _ _ _ _ _ _ _ _ _ _ _ _ _ _ _ _ _ 

thing = <module 'app.db.base' from '/home/codex/schofield/app/db/base.py'>
comp = 'DBSession', import_path = 'app.db.base.DBSession'

    def _dot_lookup(thing, comp, import_path):
        try:
            return getattr(thing, comp)
        except AttributeError:
>           __import__(import_path)
E           ModuleNotFoundError: No module named 'app.db.base.DBSession'; 'app.db.base' is not a package

/usr/lib/python3.10/unittest/mock.py:1250: ModuleNotFoundError
____________________ test_7_2_2_49_enhanced_error_semantics ____________________

mocker = <pytest_mock.plugin.MockerFixture object at 0x7ff0bce9fca0>

    def _t(mocker) -> None:
        # Apply boundary patch
>       mocked = mocker.patch(_cfg["patch"], create=True)

tests/functional/test_epic_a_data_model_functional.py:1774: 
_ _ _ _ _ _ _ _ _ _ _ _ _ _ _ _ _ _ _ _ _ _ _ _ _ _ _ _ _ _ _ _ _ _ _ _ _ _ _ _ 
../.local/lib/python3.10/site-packages/pytest_mock/plugin.py:439: in __call__
    return self._start_patch(
../.local/lib/python3.10/site-packages/pytest_mock/plugin.py:257: in _start_patch
    mocked: MockType = p.start()
/usr/lib/python3.10/unittest/mock.py:1595: in start
    result = self.__enter__()
/usr/lib/python3.10/unittest/mock.py:1431: in __enter__
    self.target = self.getter()
/usr/lib/python3.10/unittest/mock.py:1618: in <lambda>
    getter = lambda: _importer(target)
/usr/lib/python3.10/unittest/mock.py:1261: in _importer
    thing = _dot_lookup(thing, comp, import_path)
_ _ _ _ _ _ _ _ _ _ _ _ _ _ _ _ _ _ _ _ _ _ _ _ _ _ _ _ _ _ _ _ _ _ _ _ _ _ _ _ 

thing = <module 'app.db.migrations_runner' from '/home/codex/schofield/app/db/migrations_runner.py'>
comp = 'MigrationRunner'
import_path = 'app.db.migrations_runner.MigrationRunner'

    def _dot_lookup(thing, comp, import_path):
        try:
            return getattr(thing, comp)
        except AttributeError:
>           __import__(import_path)
E           ModuleNotFoundError: No module named 'app.db.migrations_runner.MigrationRunner'; 'app.db.migrations_runner' is not a package

/usr/lib/python3.10/unittest/mock.py:1250: ModuleNotFoundError
____________________ test_7_2_2_50_enhanced_error_semantics ____________________

mocker = <pytest_mock.plugin.MockerFixture object at 0x7ff0bde1ae00>

    def _t(mocker) -> None:
        # Apply boundary patch
>       mocked = mocker.patch(_cfg["patch"], create=True)

tests/functional/test_epic_a_data_model_functional.py:1774: 
_ _ _ _ _ _ _ _ _ _ _ _ _ _ _ _ _ _ _ _ _ _ _ _ _ _ _ _ _ _ _ _ _ _ _ _ _ _ _ _ 
../.local/lib/python3.10/site-packages/pytest_mock/plugin.py:439: in __call__
    return self._start_patch(
../.local/lib/python3.10/site-packages/pytest_mock/plugin.py:257: in _start_patch
    mocked: MockType = p.start()
/usr/lib/python3.10/unittest/mock.py:1595: in start
    result = self.__enter__()
/usr/lib/python3.10/unittest/mock.py:1431: in __enter__
    self.target = self.getter()
/usr/lib/python3.10/unittest/mock.py:1618: in <lambda>
    getter = lambda: _importer(target)
/usr/lib/python3.10/unittest/mock.py:1261: in _importer
    thing = _dot_lookup(thing, comp, import_path)
_ _ _ _ _ _ _ _ _ _ _ _ _ _ _ _ _ _ _ _ _ _ _ _ _ _ _ _ _ _ _ _ _ _ _ _ _ _ _ _ 

thing = <module 'app.db.base' from '/home/codex/schofield/app/db/base.py'>
comp = 'DB', import_path = 'app.db.base.DB'

    def _dot_lookup(thing, comp, import_path):
        try:
            return getattr(thing, comp)
        except AttributeError:
>           __import__(import_path)
E           ModuleNotFoundError: No module named 'app.db.base.DB'; 'app.db.base' is not a package

/usr/lib/python3.10/unittest/mock.py:1250: ModuleNotFoundError
____________________ test_7_2_2_51_enhanced_error_semantics ____________________

mocker = <pytest_mock.plugin.MockerFixture object at 0x7ff0bce9fca0>

    def _t(mocker) -> None:
        # Apply boundary patch
>       mocked = mocker.patch(_cfg["patch"], create=True)

tests/functional/test_epic_a_data_model_functional.py:1774: 
_ _ _ _ _ _ _ _ _ _ _ _ _ _ _ _ _ _ _ _ _ _ _ _ _ _ _ _ _ _ _ _ _ _ _ _ _ _ _ _ 
../.local/lib/python3.10/site-packages/pytest_mock/plugin.py:439: in __call__
    return self._start_patch(
../.local/lib/python3.10/site-packages/pytest_mock/plugin.py:257: in _start_patch
    mocked: MockType = p.start()
/usr/lib/python3.10/unittest/mock.py:1595: in start
    result = self.__enter__()
/usr/lib/python3.10/unittest/mock.py:1431: in __enter__
    self.target = self.getter()
/usr/lib/python3.10/unittest/mock.py:1618: in <lambda>
    getter = lambda: _importer(target)
/usr/lib/python3.10/unittest/mock.py:1261: in _importer
    thing = _dot_lookup(thing, comp, import_path)
_ _ _ _ _ _ _ _ _ _ _ _ _ _ _ _ _ _ _ _ _ _ _ _ _ _ _ _ _ _ _ _ _ _ _ _ _ _ _ _ 

thing = <module 'app.db.base' from '/home/codex/schofield/app/db/base.py'>
comp = 'DBSession', import_path = 'app.db.base.DBSession'

    def _dot_lookup(thing, comp, import_path):
        try:
            return getattr(thing, comp)
        except AttributeError:
>           __import__(import_path)
E           ModuleNotFoundError: No module named 'app.db.base.DBSession'; 'app.db.base' is not a package

/usr/lib/python3.10/unittest/mock.py:1250: ModuleNotFoundError
____________________ test_7_2_2_52_enhanced_error_semantics ____________________

thing = <module 'app' from '/home/codex/schofield/app/__init__.py'>
comp = 'resolution', import_path = 'app.resolution'

    def _dot_lookup(thing, comp, import_path):
        try:
>           return getattr(thing, comp)
E           AttributeError: module 'app' has no attribute 'resolution'

/usr/lib/python3.10/unittest/mock.py:1248: AttributeError

During handling of the above exception, another exception occurred:

mocker = <pytest_mock.plugin.MockerFixture object at 0x7ff0bcef5630>

    def _t(mocker) -> None:
        # Apply boundary patch
>       mocked = mocker.patch(_cfg["patch"], create=True)

tests/functional/test_epic_a_data_model_functional.py:1774: 
_ _ _ _ _ _ _ _ _ _ _ _ _ _ _ _ _ _ _ _ _ _ _ _ _ _ _ _ _ _ _ _ _ _ _ _ _ _ _ _ 
../.local/lib/python3.10/site-packages/pytest_mock/plugin.py:439: in __call__
    return self._start_patch(
../.local/lib/python3.10/site-packages/pytest_mock/plugin.py:257: in _start_patch
    mocked: MockType = p.start()
/usr/lib/python3.10/unittest/mock.py:1595: in start
    result = self.__enter__()
/usr/lib/python3.10/unittest/mock.py:1431: in __enter__
    self.target = self.getter()
/usr/lib/python3.10/unittest/mock.py:1618: in <lambda>
    getter = lambda: _importer(target)
/usr/lib/python3.10/unittest/mock.py:1261: in _importer
    thing = _dot_lookup(thing, comp, import_path)
_ _ _ _ _ _ _ _ _ _ _ _ _ _ _ _ _ _ _ _ _ _ _ _ _ _ _ _ _ _ _ _ _ _ _ _ _ _ _ _ 

thing = <module 'app' from '/home/codex/schofield/app/__init__.py'>
comp = 'resolution', import_path = 'app.resolution'

    def _dot_lookup(thing, comp, import_path):
        try:
            return getattr(thing, comp)
        except AttributeError:
>           __import__(import_path)
E           ModuleNotFoundError: No module named 'app.resolution'

/usr/lib/python3.10/unittest/mock.py:1250: ModuleNotFoundError
____________________ test_7_2_2_53_enhanced_error_semantics ____________________

thing = <module 'app' from '/home/codex/schofield/app/__init__.py'>
comp = 'encryption', import_path = 'app.encryption'

    def _dot_lookup(thing, comp, import_path):
        try:
>           return getattr(thing, comp)
E           AttributeError: module 'app' has no attribute 'encryption'

/usr/lib/python3.10/unittest/mock.py:1248: AttributeError

During handling of the above exception, another exception occurred:

mocker = <pytest_mock.plugin.MockerFixture object at 0x7ff0bccfa830>

    def _t(mocker) -> None:
        # Apply boundary patch
>       mocked = mocker.patch(_cfg["patch"], create=True)

tests/functional/test_epic_a_data_model_functional.py:1774: 
_ _ _ _ _ _ _ _ _ _ _ _ _ _ _ _ _ _ _ _ _ _ _ _ _ _ _ _ _ _ _ _ _ _ _ _ _ _ _ _ 
../.local/lib/python3.10/site-packages/pytest_mock/plugin.py:439: in __call__
    return self._start_patch(
../.local/lib/python3.10/site-packages/pytest_mock/plugin.py:257: in _start_patch
    mocked: MockType = p.start()
/usr/lib/python3.10/unittest/mock.py:1595: in start
    result = self.__enter__()
/usr/lib/python3.10/unittest/mock.py:1431: in __enter__
    self.target = self.getter()
/usr/lib/python3.10/unittest/mock.py:1618: in <lambda>
    getter = lambda: _importer(target)
/usr/lib/python3.10/unittest/mock.py:1261: in _importer
    thing = _dot_lookup(thing, comp, import_path)
_ _ _ _ _ _ _ _ _ _ _ _ _ _ _ _ _ _ _ _ _ _ _ _ _ _ _ _ _ _ _ _ _ _ _ _ _ _ _ _ 

thing = <module 'app' from '/home/codex/schofield/app/__init__.py'>
comp = 'encryption', import_path = 'app.encryption'

    def _dot_lookup(thing, comp, import_path):
        try:
            return getattr(thing, comp)
        except AttributeError:
>           __import__(import_path)
E           ModuleNotFoundError: No module named 'app.encryption'

/usr/lib/python3.10/unittest/mock.py:1250: ModuleNotFoundError
____________________ test_7_2_2_54_enhanced_error_semantics ____________________

mocker = <pytest_mock.plugin.MockerFixture object at 0x7ff0bcf4d750>

    def _t(mocker) -> None:
        # Apply boundary patch
>       mocked = mocker.patch(_cfg["patch"], create=True)

tests/functional/test_epic_a_data_model_functional.py:1774: 
_ _ _ _ _ _ _ _ _ _ _ _ _ _ _ _ _ _ _ _ _ _ _ _ _ _ _ _ _ _ _ _ _ _ _ _ _ _ _ _ 
../.local/lib/python3.10/site-packages/pytest_mock/plugin.py:439: in __call__
    return self._start_patch(
../.local/lib/python3.10/site-packages/pytest_mock/plugin.py:257: in _start_patch
    mocked: MockType = p.start()
/usr/lib/python3.10/unittest/mock.py:1595: in start
    result = self.__enter__()
/usr/lib/python3.10/unittest/mock.py:1431: in __enter__
    self.target = self.getter()
/usr/lib/python3.10/unittest/mock.py:1618: in <lambda>
    getter = lambda: _importer(target)
/usr/lib/python3.10/unittest/mock.py:1261: in _importer
    thing = _dot_lookup(thing, comp, import_path)
_ _ _ _ _ _ _ _ _ _ _ _ _ _ _ _ _ _ _ _ _ _ _ _ _ _ _ _ _ _ _ _ _ _ _ _ _ _ _ _ 

thing = <module 'app.db.base' from '/home/codex/schofield/app/db/base.py'>
comp = 'DB', import_path = 'app.db.base.DB'

    def _dot_lookup(thing, comp, import_path):
        try:
            return getattr(thing, comp)
        except AttributeError:
>           __import__(import_path)
E           ModuleNotFoundError: No module named 'app.db.base.DB'; 'app.db.base' is not a package

/usr/lib/python3.10/unittest/mock.py:1250: ModuleNotFoundError
____________________ test_7_2_2_55_enhanced_error_semantics ____________________

mocker = <pytest_mock.plugin.MockerFixture object at 0x7ff0bcf1e5c0>

    def _t(mocker) -> None:
        # Apply boundary patch
>       mocked = mocker.patch(_cfg["patch"], create=True)

tests/functional/test_epic_a_data_model_functional.py:1774: 
_ _ _ _ _ _ _ _ _ _ _ _ _ _ _ _ _ _ _ _ _ _ _ _ _ _ _ _ _ _ _ _ _ _ _ _ _ _ _ _ 
../.local/lib/python3.10/site-packages/pytest_mock/plugin.py:439: in __call__
    return self._start_patch(
../.local/lib/python3.10/site-packages/pytest_mock/plugin.py:257: in _start_patch
    mocked: MockType = p.start()
/usr/lib/python3.10/unittest/mock.py:1595: in start
    result = self.__enter__()
/usr/lib/python3.10/unittest/mock.py:1431: in __enter__
    self.target = self.getter()
/usr/lib/python3.10/unittest/mock.py:1618: in <lambda>
    getter = lambda: _importer(target)
/usr/lib/python3.10/unittest/mock.py:1261: in _importer
    thing = _dot_lookup(thing, comp, import_path)
_ _ _ _ _ _ _ _ _ _ _ _ _ _ _ _ _ _ _ _ _ _ _ _ _ _ _ _ _ _ _ _ _ _ _ _ _ _ _ _ 

thing = <module 'app.db.base' from '/home/codex/schofield/app/db/base.py'>
comp = 'DBSession', import_path = 'app.db.base.DBSession'

    def _dot_lookup(thing, comp, import_path):
        try:
            return getattr(thing, comp)
        except AttributeError:
>           __import__(import_path)
E           ModuleNotFoundError: No module named 'app.db.base.DBSession'; 'app.db.base' is not a package

/usr/lib/python3.10/unittest/mock.py:1250: ModuleNotFoundError
____________________ test_7_2_2_56_enhanced_error_semantics ____________________

mocker = <pytest_mock.plugin.MockerFixture object at 0x7ff0bcd78610>

    def _t(mocker) -> None:
        # Apply boundary patch
>       mocked = mocker.patch(_cfg["patch"], create=True)

tests/functional/test_epic_a_data_model_functional.py:1774: 
_ _ _ _ _ _ _ _ _ _ _ _ _ _ _ _ _ _ _ _ _ _ _ _ _ _ _ _ _ _ _ _ _ _ _ _ _ _ _ _ 
../.local/lib/python3.10/site-packages/pytest_mock/plugin.py:439: in __call__
    return self._start_patch(
../.local/lib/python3.10/site-packages/pytest_mock/plugin.py:257: in _start_patch
    mocked: MockType = p.start()
/usr/lib/python3.10/unittest/mock.py:1595: in start
    result = self.__enter__()
/usr/lib/python3.10/unittest/mock.py:1431: in __enter__
    self.target = self.getter()
/usr/lib/python3.10/unittest/mock.py:1618: in <lambda>
    getter = lambda: _importer(target)
/usr/lib/python3.10/unittest/mock.py:1261: in _importer
    thing = _dot_lookup(thing, comp, import_path)
_ _ _ _ _ _ _ _ _ _ _ _ _ _ _ _ _ _ _ _ _ _ _ _ _ _ _ _ _ _ _ _ _ _ _ _ _ _ _ _ 

thing = <module 'app.db.migrations_runner' from '/home/codex/schofield/app/db/migrations_runner.py'>
comp = 'MigrationRunner'
import_path = 'app.db.migrations_runner.MigrationRunner'

    def _dot_lookup(thing, comp, import_path):
        try:
            return getattr(thing, comp)
        except AttributeError:
>           __import__(import_path)
E           ModuleNotFoundError: No module named 'app.db.migrations_runner.MigrationRunner'; 'app.db.migrations_runner' is not a package

/usr/lib/python3.10/unittest/mock.py:1250: ModuleNotFoundError
____________________ test_7_2_2_57_enhanced_error_semantics ____________________

thing = <module 'app' from '/home/codex/schofield/app/__init__.py'>
comp = 'telemetry', import_path = 'app.telemetry'

    def _dot_lookup(thing, comp, import_path):
        try:
>           return getattr(thing, comp)
E           AttributeError: module 'app' has no attribute 'telemetry'

/usr/lib/python3.10/unittest/mock.py:1248: AttributeError

During handling of the above exception, another exception occurred:

mocker = <pytest_mock.plugin.MockerFixture object at 0x7ff0bcf1d750>

    def _t(mocker) -> None:
        # Apply boundary patch
>       mocked = mocker.patch(_cfg["patch"], create=True)

tests/functional/test_epic_a_data_model_functional.py:1774: 
_ _ _ _ _ _ _ _ _ _ _ _ _ _ _ _ _ _ _ _ _ _ _ _ _ _ _ _ _ _ _ _ _ _ _ _ _ _ _ _ 
../.local/lib/python3.10/site-packages/pytest_mock/plugin.py:439: in __call__
    return self._start_patch(
../.local/lib/python3.10/site-packages/pytest_mock/plugin.py:257: in _start_patch
    mocked: MockType = p.start()
/usr/lib/python3.10/unittest/mock.py:1595: in start
    result = self.__enter__()
/usr/lib/python3.10/unittest/mock.py:1431: in __enter__
    self.target = self.getter()
/usr/lib/python3.10/unittest/mock.py:1618: in <lambda>
    getter = lambda: _importer(target)
/usr/lib/python3.10/unittest/mock.py:1261: in _importer
    thing = _dot_lookup(thing, comp, import_path)
_ _ _ _ _ _ _ _ _ _ _ _ _ _ _ _ _ _ _ _ _ _ _ _ _ _ _ _ _ _ _ _ _ _ _ _ _ _ _ _ 

thing = <module 'app' from '/home/codex/schofield/app/__init__.py'>
comp = 'telemetry', import_path = 'app.telemetry'

    def _dot_lookup(thing, comp, import_path):
        try:
            return getattr(thing, comp)
        except AttributeError:
>           __import__(import_path)
E           ModuleNotFoundError: No module named 'app.telemetry'

/usr/lib/python3.10/unittest/mock.py:1250: ModuleNotFoundError
__________________ test_7_2_2_58_outputs_entities_incomplete ___________________

    def test_7_2_2_58_outputs_entities_incomplete():
        """Verifies 7.2.2.58 — Outputs: entities incomplete."""
        outputs = _get_outputs_for_contract()
        entities = outputs.get("entities")
>       assert entities is not None  # ensure presence
E       assert None is not None

tests/functional/test_epic_a_data_model_functional.py:1821: AssertionError
______________ test_7_2_2_60_outputs_entities_mutable_within_step ______________

    def test_7_2_2_60_outputs_entities_mutable_within_step():
        """Verifies 7.2.2.60 — Outputs: entities mutable within step."""
        outputs1 = _get_outputs_for_contract()
        outputs2 = _get_outputs_for_contract()
        # Both snapshots must be present and equal within the same step
>       assert outputs1 and outputs2 and outputs1 == outputs2
E       assert ({})

tests/functional/test_epic_a_data_model_functional.py:1838: AssertionError
_____________ test_7_2_2_62_outputs_entity_name_mismatch_with_erd ______________

    def test_7_2_2_62_outputs_entity_name_mismatch_with_erd():
        """Verifies 7.2.2.62 — Outputs: entity name mismatch with ERD."""
        outputs = _get_outputs_for_contract()
        names = {e.get("name") for e in (outputs.get("entities") or [])}
>       assert names == _EXPECTED_ENTITY_NAMES
E       AssertionError: assert set() == {'AnswerOptio...ldGroup', ...}
E         
E         Extra items in the right set:
E         'GroupValue'
E         'QuestionToFieldGroup'
E         'QuestionnaireQuestion'
E         'Company'
E         'ResponseSet'
E         'GeneratedDocument'
E         'AnswerOption'
E         'Response'
E         'FieldGroup'
E         
E         Full diff:
E         + set()
E         - {
E         -     'AnswerOption',
E         -     'Company',
E         -     'FieldGroup',
E         -     'GeneratedDocument',
E         -     'GroupValue',
E         -     'QuestionToFieldGroup',
E         -     'QuestionnaireQuestion',
E         -     'Response',
E         -     'ResponseSet',
E         - }

tests/functional/test_epic_a_data_model_functional.py:1852: AssertionError
___________________ test_7_2_2_64_outputs_fields_set_invalid ___________________

    def test_7_2_2_64_outputs_fields_set_invalid():
        """Verifies 7.2.2.64 — Outputs: fields set invalid."""
        outputs = _get_outputs_for_contract()
        resp = next((e for e in (outputs.get("entities") or []) if e.get("name") == "Response"), {})
        fields = {f.get("name"): f.get("type") for f in (resp.get("fields") or [])}
>       assert fields == {"response_id": "uuid", "response_set_id": "uuid", "question_id": "uuid", "value_json": "jsonb"}
E       AssertionError: assert {} == {'question_id...son': 'jsonb'}
E         
E         Right contains 4 more items:
E         {'question_id': 'uuid',
E          'response_id': 'uuid',
E          'response_set_id': 'uuid',
E          'value_json': 'jsonb'}
E         
E         Full diff:
E         + {}
E         - {
E         -     'question_id': 'uuid',
E         -     'response_id': 'uuid',
E         -     'response_set_id': 'uuid',
E         -     'value_json': 'jsonb',
E         - }

tests/functional/test_epic_a_data_model_functional.py:1867: AssertionError
______________ test_7_2_2_67_outputs_field_name_mismatch_with_erd ______________

    def test_7_2_2_67_outputs_field_name_mismatch_with_erd():
        """Verifies 7.2.2.67 — Outputs: field name mismatch with ERD."""
        outputs = _get_outputs_for_contract()
        resp = next((e for e in (outputs.get("entities") or []) if e.get("name") == "Response"), {})
        names = {f.get("name") for f in (resp.get("fields") or [])}
>       assert names == {"response_id", "response_set_id", "question_id", "value_json"}
E       AssertionError: assert set() == {'question_id... 'value_json'}
E         
E         Extra items in the right set:
E         'question_id'
E         'value_json'
E         'response_id'
E         'response_set_id'
E         
E         Full diff:
E         + set()
E         - {
E         -     'question_id',
E         -     'response_id',
E         -     'response_set_id',
E         -     'value_json',
E         - }

tests/functional/test_epic_a_data_model_functional.py:1890: AssertionError
______________ test_7_2_2_70_outputs_field_type_mismatch_with_erd ______________

    def test_7_2_2_70_outputs_field_type_mismatch_with_erd():
        """Verifies 7.2.2.70 — Outputs: field type mismatch with ERD."""
        outputs = _get_outputs_for_contract()
        resp = next((e for e in (outputs.get("entities") or []) if e.get("name") == "Response"), {})
        types = {f.get("name"): f.get("type") for f in (resp.get("fields") or [])}
>       assert types == {"response_id": "uuid", "response_set_id": "uuid", "question_id": "uuid", "value_json": "jsonb"}
E       AssertionError: assert {} == {'question_id...son': 'jsonb'}
E         
E         Right contains 4 more items:
E         {'question_id': 'uuid',
E          'response_id': 'uuid',
E          'response_set_id': 'uuid',
E          'value_json': 'jsonb'}
E         
E         Full diff:
E         + {}
E         - {
E         -     'question_id': 'uuid',
E         -     'response_id': 'uuid',
E         -     'response_set_id': 'uuid',
E         -     'value_json': 'jsonb',
E         - }

tests/functional/test_epic_a_data_model_functional.py:1914: AssertionError
___________ test_7_2_2_72_outputs_encrypted_flag_false_when_required ___________

    def test_7_2_2_72_outputs_encrypted_flag_false_when_required():
        """Verifies 7.2.2.72 — Outputs: encrypted flag false when required."""
        outputs = _get_outputs_for_contract()
        resp = next((e for e in (outputs.get("entities") or []) if e.get("name") == "Response"), {})
        fld = next((f for f in (resp.get("fields") or []) if f.get("name") == "value_json"), {})
>       assert fld.get("encrypted") is True
E       AssertionError: assert None is True
E        +  where None = <built-in method get of dict object at 0x7ff0bcffe780>('encrypted')
E        +    where <built-in method get of dict object at 0x7ff0bcffe780> = {}.get

tests/functional/test_epic_a_data_model_functional.py:1930: AssertionError
__________ test_7_2_2_78_primary_key_columns_missing_when_pk_defined ___________

    def test_7_2_2_78_primary_key_columns_missing_when_pk_defined():
        """Verifies 7.2.2.78 — Primary Key Columns Missing When PK Defined."""
        outputs = _get_outputs_for_contract()
        entities = (outputs.get("entities") or [])
        # Clarke: ensure at least one entity declares a primary_key
>       assert any(ent.get("primary_key") is not None for ent in entities)
E       assert False
E        +  where False = any(<generator object test_7_2_2_78_primary_key_columns_missing_when_pk_defined.<locals>.<genexpr> at 0x7ff0bddf3ca0>)

tests/functional/test_epic_a_data_model_functional.py:1980: AssertionError
____________________ test_7_2_2_79_foreign_keys_set_invalid ____________________

    def test_7_2_2_79_foreign_keys_set_invalid():
        """Verifies 7.2.2.79 — Foreign Keys Set Invalid."""
        outputs = _get_outputs_for_contract()
        entities = (outputs.get("entities") or [])
        # Clarke: assert presence of at least one foreign key overall
>       assert any((ent.get("foreign_keys") or []) for ent in entities)
E       assert False
E        +  where False = any(<generator object test_7_2_2_79_foreign_keys_set_invalid.<locals>.<genexpr> at 0x7ff0bddf0120>)

tests/functional/test_epic_a_data_model_functional.py:1992: AssertionError
______________ test_7_2_2_80_foreign_keys_order_not_deterministic ______________

    def test_7_2_2_80_foreign_keys_order_not_deterministic():
        """Verifies 7.2.2.80 — Foreign Keys Order Not Deterministic."""
        outputs = _get_outputs_for_contract()
        entities = (outputs.get("entities") or [])
        # Clarke: ensure foreign keys exist before order/uniqueness checks
>       assert any((ent.get("foreign_keys") or []) for ent in entities)
E       assert False
E        +  where False = any(<generator object test_7_2_2_80_foreign_keys_order_not_deterministic.<locals>.<genexpr> at 0x7ff0bcdba490>)

tests/functional/test_epic_a_data_model_functional.py:2007: AssertionError
_____________________ test_7_2_2_81_foreign_key_name_empty _____________________

    def test_7_2_2_81_foreign_key_name_empty():
        """Verifies 7.2.2.81 — Foreign Key Name Empty."""
        outputs = _get_outputs_for_contract()
        entities = (outputs.get("entities") or [])
        # Clarke: ensure at least one FK exists
>       assert any((ent.get("foreign_keys") or []) for ent in entities)
E       assert False
E        +  where False = any(<generator object test_7_2_2_81_foreign_key_name_empty.<locals>.<genexpr> at 0x7ff0bcdbb6f0>)

tests/functional/test_epic_a_data_model_functional.py:2019: AssertionError
__________________ test_7_2_2_82_foreign_key_name_not_unique ___________________

    def test_7_2_2_82_foreign_key_name_not_unique():
        """Verifies 7.2.2.82 — Foreign Key Name Not Unique."""
        outputs = _get_outputs_for_contract()
        entities = (outputs.get("entities") or [])
        # Clarke: ensure foreign keys exist before uniqueness check
>       assert any((ent.get("foreign_keys") or []) for ent in entities)
E       assert False
E        +  where False = any(<generator object test_7_2_2_82_foreign_key_name_not_unique.<locals>.<genexpr> at 0x7ff0bcdb9f50>)

tests/functional/test_epic_a_data_model_functional.py:2030: AssertionError
____________ test_7_2_2_83_foreign_key_name_missing_when_fks_exist _____________

    def test_7_2_2_83_foreign_key_name_missing_when_fks_exist():
        """Verifies 7.2.2.83 — Foreign Key Name Missing When FKs Exist."""
        outputs = _get_outputs_for_contract()
        entities = (outputs.get("entities") or [])
        # Clarke: ensure at least one non-empty FK list exists
>       assert any(ent.get("foreign_keys") for ent in entities)
E       assert False
E        +  where False = any(<generator object test_7_2_2_83_foreign_key_name_missing_when_fks_exist.<locals>.<genexpr> at 0x7ff0bcdba2d0>)

tests/functional/test_epic_a_data_model_functional.py:2041: AssertionError
__________________ test_7_2_2_84_foreign_key_columns_unknown ___________________

    def test_7_2_2_84_foreign_key_columns_unknown():
        """Verifies 7.2.2.84 — Foreign Key Columns Unknown."""
        outputs = _get_outputs_for_contract()
        entities = (outputs.get("entities") or [])
        # Clarke: assert fields and fks are present prior to subset checks
>       assert any((ent.get("fields") and ent.get("foreign_keys")) for ent in entities)
E       assert False
E        +  where False = any(<generator object test_7_2_2_84_foreign_key_columns_unknown.<locals>.<genexpr> at 0x7ff0bcf8de00>)

tests/functional/test_epic_a_data_model_functional.py:2054: AssertionError
__________ test_7_2_2_85_foreign_key_columns_order_not_deterministic ___________

    def test_7_2_2_85_foreign_key_columns_order_not_deterministic():
        """Verifies 7.2.2.85 — Foreign Key Columns Order Not Deterministic."""
        outputs = _get_outputs_for_contract()
        entities = (outputs.get("entities") or [])
        # Clarke: ensure at least one FK has columns before ordering assertion
>       assert any((fk.get("columns") or []) for ent in entities for fk in (ent.get("foreign_keys") or []))
E       assert False
E        +  where False = any(<generator object test_7_2_2_85_foreign_key_columns_order_not_deterministic.<locals>.<genexpr> at 0x7ff0bcf8c4a0>)

tests/functional/test_epic_a_data_model_functional.py:2066: AssertionError
___________ test_7_2_2_86_foreign_key_columns_missing_when_fks_exist ___________

    def test_7_2_2_86_foreign_key_columns_missing_when_fks_exist():
        """Verifies 7.2.2.86 — Foreign Key Columns Missing When FKs Exist."""
        outputs = _get_outputs_for_contract()
        entities = (outputs.get("entities") or [])
        # Clarke: ensure FKs exist before asserting columns presence
>       assert any((ent.get("foreign_keys") or []) for ent in entities)
E       assert False
E        +  where False = any(<generator object test_7_2_2_86_foreign_key_columns_missing_when_fks_exist.<locals>.<genexpr> at 0x7ff0bcf8f7d0>)

tests/functional/test_epic_a_data_model_functional.py:2078: AssertionError
_____________ test_7_2_2_87_foreign_key_references_entity_missing ______________

    def test_7_2_2_87_foreign_key_references_entity_missing():
        """Verifies 7.2.2.87 — Foreign Key References Entity Missing."""
        outputs = _get_outputs_for_contract()
        entities = (outputs.get("entities") or [])
        # Clarke: assert entities and fks exist prior to reference checks
>       assert entities
E       assert []

tests/functional/test_epic_a_data_model_functional.py:2089: AssertionError
_____________ test_7_2_2_88_foreign_key_references_columns_missing _____________

    def test_7_2_2_88_foreign_key_references_columns_missing():
        """Verifies 7.2.2.88 — Foreign Key References Columns Missing."""
        outputs = _get_outputs_for_contract()
        entities = (outputs.get("entities") or [])
        # Clarke: ensure at least one FK exists and references populated
>       assert any((ent.get("foreign_keys") or []) for ent in entities)
E       assert False
E        +  where False = any(<generator object test_7_2_2_88_foreign_key_references_columns_missing.<locals>.<genexpr> at 0x7ff0bddf0900>)

tests/functional/test_epic_a_data_model_functional.py:2102: AssertionError
_____________ test_7_2_2_89_foreign_key_references_entity_unknown ______________

    def test_7_2_2_89_foreign_key_references_entity_unknown():
        """Verifies 7.2.2.89 — Foreign Key References Entity Unknown."""
        outputs = _get_outputs_for_contract()
        entities = (outputs.get("entities") or [])
        # Clarke: assert entities and fks exist prior to membership checks
>       assert entities
E       assert []

tests/functional/test_epic_a_data_model_functional.py:2114: AssertionError
_____________ test_7_2_2_90_foreign_key_references_columns_unknown _____________

    def test_7_2_2_90_foreign_key_references_columns_unknown():
        """Verifies 7.2.2.90 — Foreign Key References Columns Unknown."""
        outputs = _get_outputs_for_contract()
        # This requires cross-entity column validation; ensure presence first
        entities = (outputs.get("entities") or [])
>       assert any((ent.get("foreign_keys") or []) for ent in entities)
E       assert False
E        +  where False = any(<generator object test_7_2_2_90_foreign_key_references_columns_unknown.<locals>.<genexpr> at 0x7ff0bcf8b140>)

tests/functional/test_epic_a_data_model_functional.py:2127: AssertionError
_________ test_7_2_2_91_foreign_key_references_columns_count_mismatch __________

    def test_7_2_2_91_foreign_key_references_columns_count_mismatch():
        """Verifies 7.2.2.91 — Foreign Key References Columns Count Mismatch."""
        outputs = _get_outputs_for_contract()
        entities = (outputs.get("entities") or [])
        # Clarke: assert both fk and referenced columns exist before length compare
>       assert any((fk.get("columns") and (fk.get("references") or {}).get("columns"))
                   for ent in entities for fk in (ent.get("foreign_keys") or []))
E       assert False
E        +  where False = any(<generator object test_7_2_2_91_foreign_key_references_columns_count_mismatch.<locals>.<genexpr> at 0x7ff0bcf8a490>)

tests/functional/test_epic_a_data_model_functional.py:2139: AssertionError
_________________ test_7_2_2_92_unique_constraints_set_invalid _________________

    def test_7_2_2_92_unique_constraints_set_invalid():
        """Verifies 7.2.2.92 — Unique Constraints Set Invalid."""
        outputs = _get_outputs_for_contract()
        entities = (outputs.get("entities") or [])
        # Clarke: assert unique_constraints exist before inner structure checks
>       assert any((ent.get("unique_constraints") or []) for ent in entities)
E       assert False
E        +  where False = any(<generator object test_7_2_2_92_unique_constraints_set_invalid.<locals>.<genexpr> at 0x7ff0bcf8a7a0>)

tests/functional/test_epic_a_data_model_functional.py:2153: AssertionError
___________ test_7_2_2_93_unique_constraints_order_not_deterministic ___________

    def test_7_2_2_93_unique_constraints_order_not_deterministic():
        """Verifies 7.2.2.93 — Unique Constraints Order Not Deterministic."""
        outputs = _get_outputs_for_contract()
        entities = (outputs.get("entities") or [])
        # Clarke: ensure unique constraints exist before order check
>       assert any((ent.get("unique_constraints") or []) for ent in entities)
E       assert False
E        +  where False = any(<generator object test_7_2_2_93_unique_constraints_order_not_deterministic.<locals>.<genexpr> at 0x7ff0bcdb9a10>)

tests/functional/test_epic_a_data_model_functional.py:2165: AssertionError
__________________ test_7_2_2_94_unique_constraint_name_empty __________________

    def test_7_2_2_94_unique_constraint_name_empty():
        """Verifies 7.2.2.94 — Unique Constraint Name Empty."""
        outputs = _get_outputs_for_contract()
        entities = (outputs.get("entities") or [])
        # Clarke: ensure unique constraints exist before name checks
>       assert any((ent.get("unique_constraints") or []) for ent in entities)
E       assert False
E        +  where False = any(<generator object test_7_2_2_94_unique_constraint_name_empty.<locals>.<genexpr> at 0x7ff0bcdb9d20>)

tests/functional/test_epic_a_data_model_functional.py:2176: AssertionError
_______________ test_7_2_2_95_unique_constraint_name_not_unique ________________

    def test_7_2_2_95_unique_constraint_name_not_unique():
        """Verifies 7.2.2.95 — Unique Constraint Name Not Unique."""
        outputs = _get_outputs_for_contract()
        entities = (outputs.get("entities") or [])
        # Clarke: ensure unique constraints exist before uniqueness check
>       assert any((ent.get("unique_constraints") or []) for ent in entities)
E       assert False
E        +  where False = any(<generator object test_7_2_2_95_unique_constraint_name_not_unique.<locals>.<genexpr> at 0x7ff0bcf8eb90>)

tests/functional/test_epic_a_data_model_functional.py:2187: AssertionError
_______ test_7_2_2_96_unique_constraint_name_missing_when_uniques_exist ________

    def test_7_2_2_96_unique_constraint_name_missing_when_uniques_exist():
        """Verifies 7.2.2.96 — Unique Constraint Name Missing When Uniques Exist."""
        outputs = _get_outputs_for_contract()
        entities = (outputs.get("entities") or [])
        # Clarke: ensure at least one entity exposes unique_constraints
>       assert any((ent.get("unique_constraints") or []) for ent in entities)
E       assert False
E        +  where False = any(<generator object test_7_2_2_96_unique_constraint_name_missing_when_uniques_exist.<locals>.<genexpr> at 0x7ff0bcf8d4d0>)

tests/functional/test_epic_a_data_model_functional.py:2198: AssertionError
_______________ test_7_2_2_97_unique_constraint_columns_unknown ________________

    def test_7_2_2_97_unique_constraint_columns_unknown():
        """Verifies 7.2.2.97 — Unique Constraint Columns Unknown."""
        outputs = _get_outputs_for_contract()
        entities = (outputs.get("entities") or [])
        # Clarke: assert fields and unique_constraints exist before subset checks
>       assert any((ent.get("fields") and ent.get("unique_constraints")) for ent in entities)
E       assert False
E        +  where False = any(<generator object test_7_2_2_97_unique_constraint_columns_unknown.<locals>.<genexpr> at 0x7ff0bcf8cf20>)

tests/functional/test_epic_a_data_model_functional.py:2211: AssertionError
_______ test_7_2_2_98_unique_constraint_columns_order_not_deterministic ________

    def test_7_2_2_98_unique_constraint_columns_order_not_deterministic():
        """Verifies 7.2.2.98 — Unique Constraint Columns Order Not Deterministic."""
        outputs = _get_outputs_for_contract()
        entities = (outputs.get("entities") or [])
        # Clarke: ensure columns exist before ordering assert
>       assert any((uq.get("columns") or []) for ent in entities for uq in (ent.get("unique_constraints") or []))
E       assert False
E        +  where False = any(<generator object test_7_2_2_98_unique_constraint_columns_order_not_deterministic.<locals>.<genexpr> at 0x7ff0bcf8d000>)

tests/functional/test_epic_a_data_model_functional.py:2223: AssertionError
______ test_7_2_2_99_unique_constraint_columns_missing_when_uniques_exist ______

    def test_7_2_2_99_unique_constraint_columns_missing_when_uniques_exist():
        """Verifies 7.2.2.99 — Unique Constraint Columns Missing When Uniques Exist."""
        outputs = _get_outputs_for_contract()
        entities = (outputs.get("entities") or [])
        # Clarke: ensure unique constraints exist before asserting columns presence
>       assert any((ent.get("unique_constraints") or []) for ent in entities)
E       assert False
E        +  where False = any(<generator object test_7_2_2_99_unique_constraint_columns_missing_when_uniques_exist.<locals>.<genexpr> at 0x7ff0bddf0c10>)

tests/functional/test_epic_a_data_model_functional.py:2235: AssertionError
_______________________ test_7_2_2_108_enums_incomplete ________________________

    def test_7_2_2_108_enums_incomplete():
        """Verifies 7.2.2.108 — Enums Incomplete."""
        outputs = _get_outputs_for_contract()
        enums = outputs.get("enums") or []
        ak = next((e for e in enums if e.get("name") == "answer_kind"), None)
>       assert ak is not None and ak.get("values") == ["boolean", "enum_single", "long_text", "number", "short_string"]
E       assert (None is not None)

tests/functional/test_epic_a_data_model_functional.py:2315: AssertionError
__________________ test_7_2_2_111_enum_name_mismatch_with_erd __________________

    def test_7_2_2_111_enum_name_mismatch_with_erd():
        """Verifies 7.2.2.111 — Enum Name Mismatch With ERD."""
        outputs = _get_outputs_for_contract()
        names = {e.get("name") for e in (outputs.get("enums") or [])}
>       assert {"answer_kind"}.issubset(names)
E       AssertionError: assert False
E        +  where False = <built-in method issubset of set object at 0x7ff0bcdb0900>(set())
E        +    where <built-in method issubset of set object at 0x7ff0bcdb0900> = {'answer_kind'}.issubset

tests/functional/test_epic_a_data_model_functional.py:2337: AssertionError
_________________ test_7_2_2_114_enum_values_mismatch_with_erd _________________

    def test_7_2_2_114_enum_values_mismatch_with_erd():
        """Verifies 7.2.2.114 — Enum Values Mismatch With ERD."""
        outputs = _get_outputs_for_contract()
        ak = next((e for e in (outputs.get("enums") or []) if e.get("name") == "answer_kind"), {})
>       assert set(ak.get("values") or []) == {"boolean", "enum_single", "long_text", "number", "short_string"}
E       AssertionError: assert set() == {'boolean', '...short_string'}
E         
E         Extra items in the right set:
E         'long_text'
E         'number'
E         'short_string'
E         'boolean'
E         'enum_single'
E         
E         Full diff:
E         + set()
E         - {
E         -     'boolean',
E         -     'enum_single',
E         -     'long_text',
E         -     'number',
E         -     'short_string',
E         - }

tests/functional/test_epic_a_data_model_functional.py:2360: AssertionError
__________________ test_7_2_2_117_encrypted_fields_incomplete __________________

    def test_7_2_2_117_encrypted_fields_incomplete():
        """Verifies 7.2.2.117 — Encrypted Fields Incomplete."""
        outputs = _get_outputs_for_contract()
        manifest = set(outputs.get("encrypted_fields") or [])
        expected = {"Company.legal_name", "Company.registered_office_address", "Response.value_json", "GeneratedDocument.output_uri"}
>       assert manifest == expected
E       AssertionError: assert set() == {'Company.leg...e.value_json'}
E         
E         Extra items in the right set:
E         'Company.legal_name'
E         'GeneratedDocument.output_uri'
E         'Response.value_json'
E         'Company.registered_office_address'
E         
E         Full diff:
E         + set()
E         - {
E         -     'Company.legal_name',
E         -     'Company.registered_office_address',
E         -     'GeneratedDocument.output_uri',
E         -     'Response.value_json',
E         - }

tests/functional/test_epic_a_data_model_functional.py:2383: AssertionError
________________ test_7_2_2_120_constraints_applied_incomplete _________________

    def test_7_2_2_120_constraints_applied_incomplete():
        """Verifies 7.2.2.120 — Constraints Applied Incomplete."""
        outputs = _get_outputs_for_contract()
        constraints = set(outputs.get("constraints_applied") or [])
        required = {"pk_response", "fk_response_set", "uq_response_set_question"}
>       assert required.issubset(constraints)
E       AssertionError: assert False
E        +  where False = <built-in method issubset of set object at 0x7ff0bcdb04a0>(set())
E        +    where <built-in method issubset of set object at 0x7ff0bcdb04a0> = {'fk_response_set', 'pk_response', 'uq_response_set_question'}.issubset

tests/functional/test_epic_a_data_model_functional.py:2405: AssertionError
____________________ test_7_2_2_124_migration_journal_empty ____________________

    def test_7_2_2_124_migration_journal_empty():
        """Verifies 7.2.2.124 — Migration Journal Empty."""
        outputs = _get_outputs_for_contract()
>       assert (outputs.get("migration_journal") or [])
E       AssertionError: assert (None or [])
E        +  where None = <built-in method get of dict object at 0x7ff0bd093a00>('migration_journal')
E        +    where <built-in method get of dict object at 0x7ff0bd093a00> = {}.get

tests/functional/test_epic_a_data_model_functional.py:2432: AssertionError
=========================== short test summary info ============================
FAILED tests/functional/test_epic_a_data_model_functional.py::test_7_2_1_12_migration_journal_includes_timestamps - assert False
 +  where False = all(<generator object test_7_2_1_12_migration_journal_includes_timestamps.<locals>.<genexpr> at 0x7ff0bce544a0>)
FAILED tests/functional/test_epic_a_data_model_functional.py::test_7_2_1_17_deterministic_ordering_of_artefacts - TypeError: '<' not supported between instances of 'NoneType' and 'NoneType'
FAILED tests/functional/test_epic_a_data_model_functional.py::test_7_2_2_3_erd_spec_schema_mismatch - TypeError: test_7_2_2_3_erd_spec_schema_mismatch.<locals>._FH.read() takes 1 positional argument but 2 were given
FAILED tests/functional/test_epic_a_data_model_functional.py::test_7_3_1_6_direct_lookup_follows_row_validation - AssertionError: assert ['validate_row'] == ['validate_ro...okup_by_code']
  
  Right contains one more item: 'lookup_by_code'
  
  Full diff:
    [
        'validate_row',
  -     'lookup_by_code',
    ]
FAILED tests/functional/test_epic_a_data_model_functional.py::test_7_3_1_7_placeholder_resolution_follows_direct_lookup - AssertionError: assert [] == ['lookup_by_c...placeholders']
  
  Right contains 2 more items, first extra item: 'lookup_by_code'
  
  Full diff:
  + []
  - [
  -     'lookup_by_code',
  -     'resolve_placeholders',
  - ]
FAILED tests/functional/test_epic_a_data_model_functional.py::test_7_3_1_9_determinism_check_precedes_next_step - ModuleNotFoundError: No module named 'app.determinism'
FAILED tests/functional/test_epic_a_data_model_functional.py::test_7_3_1_11_template_registration_reuses_schema - ModuleNotFoundError: No module named 'app.registry'
FAILED tests/functional/test_epic_a_data_model_functional.py::test_7_3_1_12_policy_registration_reuses_schema - ModuleNotFoundError: No module named 'app.registry'
FAILED tests/functional/test_epic_a_data_model_functional.py::test_7_3_2_8_halt_on_invalid_encryption_key - ModuleNotFoundError: No module named 'app.encryption'
FAILED tests/functional/test_epic_a_data_model_functional.py::test_7_3_2_9_halt_when_tls_materials_unavailable - ModuleNotFoundError: No module named 'app.security'
FAILED tests/functional/test_epic_a_data_model_functional.py::test_7_3_2_10_halt_on_unsupported_data_type - ModuleNotFoundError: No module named 'app.validation'
FAILED tests/functional/test_epic_a_data_model_functional.py::test_7_3_2_11_halt_on_out_of_order_migration - ModuleNotFoundError: No module named 'app.db.migrations_runner.MigrationRunner'; 'app.db.migrations_runner' is not a package
FAILED tests/functional/test_epic_a_data_model_functional.py::test_7_3_2_12_halt_on_unidentified_runtime_error - ModuleNotFoundError: No module named 'app.telemetry'
FAILED tests/functional/test_epic_a_data_model_functional.py::test_7_3_2_13_db_connectivity_failure_halting_step - ModuleNotFoundError: No module named 'app.db.base.DB'; 'app.db.base' is not a package
FAILED tests/functional/test_epic_a_data_model_functional.py::test_7_3_2_14_db_permission_failure_prevents_schema_creation - ModuleNotFoundError: No module named 'app.db.base.DB'; 'app.db.base' is not a package
FAILED tests/functional/test_epic_a_data_model_functional.py::test_7_3_2_15_tls_handshake_failure_prevents_inserts - ModuleNotFoundError: No module named 'app.db.base.DB'; 'app.db.base' is not a package
FAILED tests/functional/test_epic_a_data_model_functional.py::test_7_3_2_16_db_storage_exhaustion_prevents_journal_updates - ModuleNotFoundError: No module named 'app.db.base.DB'; 'app.db.base' is not a package
FAILED tests/functional/test_epic_a_data_model_functional.py::test_7_3_2_17_temp_fs_unavailable_prevents_step_continuation - ModuleNotFoundError: No module named 'app.fs'
FAILED tests/functional/test_epic_a_data_model_functional.py::test_7_3_2_18_kms_unavailability_halts_encryption - ModuleNotFoundError: No module named 'app.encryption'
FAILED tests/functional/test_epic_a_data_model_functional.py::test_7_3_2_19_time_sync_failure_halts_step - ModuleNotFoundError: No module named 'app.time'
FAILED tests/functional/test_epic_a_data_model_functional.py::test_7_3_2_20_config_dependency_unavailable_prevents_start - ModuleNotFoundError: No module named 'app.config.loader'; 'app.config' is not a package
FAILED tests/functional/test_epic_a_data_model_functional.py::test_7_2_2_22_enhanced_error_semantics - ModuleNotFoundError: No module named 'app.db.base.DB'; 'app.db.base' is not a package
FAILED tests/functional/test_epic_a_data_model_functional.py::test_7_2_2_23_enhanced_error_semantics - ModuleNotFoundError: No module named 'app.db.base.DB'; 'app.db.base' is not a package
FAILED tests/functional/test_epic_a_data_model_functional.py::test_7_2_2_24_enhanced_error_semantics - ModuleNotFoundError: No module named 'app.net'
FAILED tests/functional/test_epic_a_data_model_functional.py::test_7_2_2_25_enhanced_error_semantics - ModuleNotFoundError: No module named 'app.db.base.DB'; 'app.db.base' is not a package
FAILED tests/functional/test_epic_a_data_model_functional.py::test_7_2_2_26_enhanced_error_semantics - ModuleNotFoundError: No module named 'app.db.base.DB'; 'app.db.base' is not a package
FAILED tests/functional/test_epic_a_data_model_functional.py::test_7_2_2_27_enhanced_error_semantics - ModuleNotFoundError: No module named 'app.db.base.DB'; 'app.db.base' is not a package
FAILED tests/functional/test_epic_a_data_model_functional.py::test_7_2_2_28_enhanced_error_semantics - ModuleNotFoundError: No module named 'app.db.migrations_runner.MigrationRunner'; 'app.db.migrations_runner' is not a package
FAILED tests/functional/test_epic_a_data_model_functional.py::test_7_2_2_29_enhanced_error_semantics - ModuleNotFoundError: No module named 'app.encryption'
FAILED tests/functional/test_epic_a_data_model_functional.py::test_7_2_2_30_enhanced_error_semantics - ModuleNotFoundError: No module named 'app.encryption'
FAILED tests/functional/test_epic_a_data_model_functional.py::test_7_2_2_31_enhanced_error_semantics - ModuleNotFoundError: No module named 'app.encryption'
FAILED tests/functional/test_epic_a_data_model_functional.py::test_7_2_2_32_enhanced_error_semantics - ModuleNotFoundError: No module named 'app.encryption'
FAILED tests/functional/test_epic_a_data_model_functional.py::test_7_2_2_33_enhanced_error_semantics - ModuleNotFoundError: No module named 'app.encryption'
FAILED tests/functional/test_epic_a_data_model_functional.py::test_7_2_2_34_enhanced_error_semantics - ModuleNotFoundError: No module named 'app.cache'
FAILED tests/functional/test_epic_a_data_model_functional.py::test_7_2_2_35_enhanced_error_semantics - ModuleNotFoundError: No module named 'app.secrets'
FAILED tests/functional/test_epic_a_data_model_functional.py::test_7_2_2_36_enhanced_error_semantics - ModuleNotFoundError: No module named 'app.db.base.DB'; 'app.db.base' is not a package
FAILED tests/functional/test_epic_a_data_model_functional.py::test_7_2_2_37_enhanced_error_semantics - ModuleNotFoundError: No module named 'app.logging'
FAILED tests/functional/test_epic_a_data_model_functional.py::test_7_2_2_38_enhanced_error_semantics - ModuleNotFoundError: No module named 'app.db.base.DB'; 'app.db.base' is not a package
FAILED tests/functional/test_epic_a_data_model_functional.py::test_7_2_2_39_enhanced_error_semantics - ModuleNotFoundError: No module named 'app.db.base.DB'; 'app.db.base' is not a package
FAILED tests/functional/test_epic_a_data_model_functional.py::test_7_2_2_40_enhanced_error_semantics - ModuleNotFoundError: No module named 'app.db.base.DB'; 'app.db.base' is not a package
FAILED tests/functional/test_epic_a_data_model_functional.py::test_7_2_2_41_enhanced_error_semantics - ModuleNotFoundError: No module named 'app.db.migrations_runner.MigrationRunner'; 'app.db.migrations_runner' is not a package
FAILED tests/functional/test_epic_a_data_model_functional.py::test_7_2_2_42_enhanced_error_semantics - ModuleNotFoundError: No module named 'app.db.migrations_runner.MigrationRunner'; 'app.db.migrations_runner' is not a package
FAILED tests/functional/test_epic_a_data_model_functional.py::test_7_2_2_43_enhanced_error_semantics - ModuleNotFoundError: No module named 'app.db.migrations_runner.MigrationRunner'; 'app.db.migrations_runner' is not a package
FAILED tests/functional/test_epic_a_data_model_functional.py::test_7_2_2_44_enhanced_error_semantics - ModuleNotFoundError: No module named 'app.db.migrations_runner.MigrationRunner'; 'app.db.migrations_runner' is not a package
FAILED tests/functional/test_epic_a_data_model_functional.py::test_7_2_2_45_enhanced_error_semantics - ModuleNotFoundError: No module named 'app.db.migrations_runner.MigrationRunner'; 'app.db.migrations_runner' is not a package
FAILED tests/functional/test_epic_a_data_model_functional.py::test_7_2_2_46_enhanced_error_semantics - ModuleNotFoundError: No module named 'app.db.migrations_runner.MigrationRunner'; 'app.db.migrations_runner' is not a package
FAILED tests/functional/test_epic_a_data_model_functional.py::test_7_2_2_47_enhanced_error_semantics - ModuleNotFoundError: No module named 'app.db.migrations_runner.MigrationRunner'; 'app.db.migrations_runner' is not a package
FAILED tests/functional/test_epic_a_data_model_functional.py::test_7_2_2_48_enhanced_error_semantics - ModuleNotFoundError: No module named 'app.db.base.DBSession'; 'app.db.base' is not a package
FAILED tests/functional/test_epic_a_data_model_functional.py::test_7_2_2_49_enhanced_error_semantics - ModuleNotFoundError: No module named 'app.db.migrations_runner.MigrationRunner'; 'app.db.migrations_runner' is not a package
FAILED tests/functional/test_epic_a_data_model_functional.py::test_7_2_2_50_enhanced_error_semantics - ModuleNotFoundError: No module named 'app.db.base.DB'; 'app.db.base' is not a package
FAILED tests/functional/test_epic_a_data_model_functional.py::test_7_2_2_51_enhanced_error_semantics - ModuleNotFoundError: No module named 'app.db.base.DBSession'; 'app.db.base' is not a package
FAILED tests/functional/test_epic_a_data_model_functional.py::test_7_2_2_52_enhanced_error_semantics - ModuleNotFoundError: No module named 'app.resolution'
FAILED tests/functional/test_epic_a_data_model_functional.py::test_7_2_2_53_enhanced_error_semantics - ModuleNotFoundError: No module named 'app.encryption'
FAILED tests/functional/test_epic_a_data_model_functional.py::test_7_2_2_54_enhanced_error_semantics - ModuleNotFoundError: No module named 'app.db.base.DB'; 'app.db.base' is not a package
FAILED tests/functional/test_epic_a_data_model_functional.py::test_7_2_2_55_enhanced_error_semantics - ModuleNotFoundError: No module named 'app.db.base.DBSession'; 'app.db.base' is not a package
FAILED tests/functional/test_epic_a_data_model_functional.py::test_7_2_2_56_enhanced_error_semantics - ModuleNotFoundError: No module named 'app.db.migrations_runner.MigrationRunner'; 'app.db.migrations_runner' is not a package
FAILED tests/functional/test_epic_a_data_model_functional.py::test_7_2_2_57_enhanced_error_semantics - ModuleNotFoundError: No module named 'app.telemetry'
FAILED tests/functional/test_epic_a_data_model_functional.py::test_7_2_2_58_outputs_entities_incomplete - assert None is not None
FAILED tests/functional/test_epic_a_data_model_functional.py::test_7_2_2_60_outputs_entities_mutable_within_step - assert ({})
FAILED tests/functional/test_epic_a_data_model_functional.py::test_7_2_2_62_outputs_entity_name_mismatch_with_erd - AssertionError: assert set() == {'AnswerOptio...ldGroup', ...}
  
  Extra items in the right set:
  'GroupValue'
  'QuestionToFieldGroup'
  'QuestionnaireQuestion'
  'Company'
  'ResponseSet'
  'GeneratedDocument'
  'AnswerOption'
  'Response'
  'FieldGroup'
  
  Full diff:
  + set()
  - {
  -     'AnswerOption',
  -     'Company',
  -     'FieldGroup',
  -     'GeneratedDocument',
  -     'GroupValue',
  -     'QuestionToFieldGroup',
  -     'QuestionnaireQuestion',
  -     'Response',
  -     'ResponseSet',
  - }
FAILED tests/functional/test_epic_a_data_model_functional.py::test_7_2_2_64_outputs_fields_set_invalid - AssertionError: assert {} == {'question_id...son': 'jsonb'}
  
  Right contains 4 more items:
  {'question_id': 'uuid',
   'response_id': 'uuid',
   'response_set_id': 'uuid',
   'value_json': 'jsonb'}
  
  Full diff:
  + {}
  - {
  -     'question_id': 'uuid',
  -     'response_id': 'uuid',
  -     'response_set_id': 'uuid',
  -     'value_json': 'jsonb',
  - }
FAILED tests/functional/test_epic_a_data_model_functional.py::test_7_2_2_67_outputs_field_name_mismatch_with_erd - AssertionError: assert set() == {'question_id... 'value_json'}
  
  Extra items in the right set:
  'question_id'
  'value_json'
  'response_id'
  'response_set_id'
  
  Full diff:
  + set()
  - {
  -     'question_id',
  -     'response_id',
  -     'response_set_id',
  -     'value_json',
  - }
FAILED tests/functional/test_epic_a_data_model_functional.py::test_7_2_2_70_outputs_field_type_mismatch_with_erd - AssertionError: assert {} == {'question_id...son': 'jsonb'}
  
  Right contains 4 more items:
  {'question_id': 'uuid',
   'response_id': 'uuid',
   'response_set_id': 'uuid',
   'value_json': 'jsonb'}
  
  Full diff:
  + {}
  - {
  -     'question_id': 'uuid',
  -     'response_id': 'uuid',
  -     'response_set_id': 'uuid',
  -     'value_json': 'jsonb',
  - }
FAILED tests/functional/test_epic_a_data_model_functional.py::test_7_2_2_72_outputs_encrypted_flag_false_when_required - AssertionError: assert None is True
 +  where None = <built-in method get of dict object at 0x7ff0bcffe780>('encrypted')
 +    where <built-in method get of dict object at 0x7ff0bcffe780> = {}.get
FAILED tests/functional/test_epic_a_data_model_functional.py::test_7_2_2_78_primary_key_columns_missing_when_pk_defined - assert False
 +  where False = any(<generator object test_7_2_2_78_primary_key_columns_missing_when_pk_defined.<locals>.<genexpr> at 0x7ff0bddf3ca0>)
FAILED tests/functional/test_epic_a_data_model_functional.py::test_7_2_2_79_foreign_keys_set_invalid - assert False
 +  where False = any(<generator object test_7_2_2_79_foreign_keys_set_invalid.<locals>.<genexpr> at 0x7ff0bddf0120>)
FAILED tests/functional/test_epic_a_data_model_functional.py::test_7_2_2_80_foreign_keys_order_not_deterministic - assert False
 +  where False = any(<generator object test_7_2_2_80_foreign_keys_order_not_deterministic.<locals>.<genexpr> at 0x7ff0bcdba490>)
FAILED tests/functional/test_epic_a_data_model_functional.py::test_7_2_2_81_foreign_key_name_empty - assert False
 +  where False = any(<generator object test_7_2_2_81_foreign_key_name_empty.<locals>.<genexpr> at 0x7ff0bcdbb6f0>)
FAILED tests/functional/test_epic_a_data_model_functional.py::test_7_2_2_82_foreign_key_name_not_unique - assert False
 +  where False = any(<generator object test_7_2_2_82_foreign_key_name_not_unique.<locals>.<genexpr> at 0x7ff0bcdb9f50>)
FAILED tests/functional/test_epic_a_data_model_functional.py::test_7_2_2_83_foreign_key_name_missing_when_fks_exist - assert False
 +  where False = any(<generator object test_7_2_2_83_foreign_key_name_missing_when_fks_exist.<locals>.<genexpr> at 0x7ff0bcdba2d0>)
FAILED tests/functional/test_epic_a_data_model_functional.py::test_7_2_2_84_foreign_key_columns_unknown - assert False
 +  where False = any(<generator object test_7_2_2_84_foreign_key_columns_unknown.<locals>.<genexpr> at 0x7ff0bcf8de00>)
FAILED tests/functional/test_epic_a_data_model_functional.py::test_7_2_2_85_foreign_key_columns_order_not_deterministic - assert False
 +  where False = any(<generator object test_7_2_2_85_foreign_key_columns_order_not_deterministic.<locals>.<genexpr> at 0x7ff0bcf8c4a0>)
FAILED tests/functional/test_epic_a_data_model_functional.py::test_7_2_2_86_foreign_key_columns_missing_when_fks_exist - assert False
 +  where False = any(<generator object test_7_2_2_86_foreign_key_columns_missing_when_fks_exist.<locals>.<genexpr> at 0x7ff0bcf8f7d0>)
FAILED tests/functional/test_epic_a_data_model_functional.py::test_7_2_2_87_foreign_key_references_entity_missing - assert []
FAILED tests/functional/test_epic_a_data_model_functional.py::test_7_2_2_88_foreign_key_references_columns_missing - assert False
 +  where False = any(<generator object test_7_2_2_88_foreign_key_references_columns_missing.<locals>.<genexpr> at 0x7ff0bddf0900>)
FAILED tests/functional/test_epic_a_data_model_functional.py::test_7_2_2_89_foreign_key_references_entity_unknown - assert []
FAILED tests/functional/test_epic_a_data_model_functional.py::test_7_2_2_90_foreign_key_references_columns_unknown - assert False
 +  where False = any(<generator object test_7_2_2_90_foreign_key_references_columns_unknown.<locals>.<genexpr> at 0x7ff0bcf8b140>)
FAILED tests/functional/test_epic_a_data_model_functional.py::test_7_2_2_91_foreign_key_references_columns_count_mismatch - assert False
 +  where False = any(<generator object test_7_2_2_91_foreign_key_references_columns_count_mismatch.<locals>.<genexpr> at 0x7ff0bcf8a490>)
FAILED tests/functional/test_epic_a_data_model_functional.py::test_7_2_2_92_unique_constraints_set_invalid - assert False
 +  where False = any(<generator object test_7_2_2_92_unique_constraints_set_invalid.<locals>.<genexpr> at 0x7ff0bcf8a7a0>)
FAILED tests/functional/test_epic_a_data_model_functional.py::test_7_2_2_93_unique_constraints_order_not_deterministic - assert False
 +  where False = any(<generator object test_7_2_2_93_unique_constraints_order_not_deterministic.<locals>.<genexpr> at 0x7ff0bcdb9a10>)
FAILED tests/functional/test_epic_a_data_model_functional.py::test_7_2_2_94_unique_constraint_name_empty - assert False
 +  where False = any(<generator object test_7_2_2_94_unique_constraint_name_empty.<locals>.<genexpr> at 0x7ff0bcdb9d20>)
FAILED tests/functional/test_epic_a_data_model_functional.py::test_7_2_2_95_unique_constraint_name_not_unique - assert False
 +  where False = any(<generator object test_7_2_2_95_unique_constraint_name_not_unique.<locals>.<genexpr> at 0x7ff0bcf8eb90>)
FAILED tests/functional/test_epic_a_data_model_functional.py::test_7_2_2_96_unique_constraint_name_missing_when_uniques_exist - assert False
 +  where False = any(<generator object test_7_2_2_96_unique_constraint_name_missing_when_uniques_exist.<locals>.<genexpr> at 0x7ff0bcf8d4d0>)
FAILED tests/functional/test_epic_a_data_model_functional.py::test_7_2_2_97_unique_constraint_columns_unknown - assert False
 +  where False = any(<generator object test_7_2_2_97_unique_constraint_columns_unknown.<locals>.<genexpr> at 0x7ff0bcf8cf20>)
FAILED tests/functional/test_epic_a_data_model_functional.py::test_7_2_2_98_unique_constraint_columns_order_not_deterministic - assert False
 +  where False = any(<generator object test_7_2_2_98_unique_constraint_columns_order_not_deterministic.<locals>.<genexpr> at 0x7ff0bcf8d000>)
FAILED tests/functional/test_epic_a_data_model_functional.py::test_7_2_2_99_unique_constraint_columns_missing_when_uniques_exist - assert False
 +  where False = any(<generator object test_7_2_2_99_unique_constraint_columns_missing_when_uniques_exist.<locals>.<genexpr> at 0x7ff0bddf0c10>)
FAILED tests/functional/test_epic_a_data_model_functional.py::test_7_2_2_108_enums_incomplete - assert (None is not None)
FAILED tests/functional/test_epic_a_data_model_functional.py::test_7_2_2_111_enum_name_mismatch_with_erd - AssertionError: assert False
 +  where False = <built-in method issubset of set object at 0x7ff0bcdb0900>(set())
 +    where <built-in method issubset of set object at 0x7ff0bcdb0900> = {'answer_kind'}.issubset
FAILED tests/functional/test_epic_a_data_model_functional.py::test_7_2_2_114_enum_values_mismatch_with_erd - AssertionError: assert set() == {'boolean', '...short_string'}
  
  Extra items in the right set:
  'long_text'
  'number'
  'short_string'
  'boolean'
  'enum_single'
  
  Full diff:
  + set()
  - {
  -     'boolean',
  -     'enum_single',
  -     'long_text',
  -     'number',
  -     'short_string',
  - }
FAILED tests/functional/test_epic_a_data_model_functional.py::test_7_2_2_117_encrypted_fields_incomplete - AssertionError: assert set() == {'Company.leg...e.value_json'}
  
  Extra items in the right set:
  'Company.legal_name'
  'GeneratedDocument.output_uri'
  'Response.value_json'
  'Company.registered_office_address'
  
  Full diff:
  + set()
  - {
  -     'Company.legal_name',
  -     'Company.registered_office_address',
  -     'GeneratedDocument.output_uri',
  -     'Response.value_json',
  - }
FAILED tests/functional/test_epic_a_data_model_functional.py::test_7_2_2_120_constraints_applied_incomplete - AssertionError: assert False
 +  where False = <built-in method issubset of set object at 0x7ff0bcdb04a0>(set())
 +    where <built-in method issubset of set object at 0x7ff0bcdb04a0> = {'fk_response_set', 'pk_response', 'uq_response_set_question'}.issubset
FAILED tests/functional/test_epic_a_data_model_functional.py::test_7_2_2_124_migration_journal_empty - AssertionError: assert (None or [])
 +  where None = <built-in method get of dict object at 0x7ff0bd093a00>('migration_journal')
 +    where <built-in method get of dict object at 0x7ff0bd093a00> = {}.get
================== 92 failed, 97 passed, 1 xfailed in 20.52s ===================
