============================= test session starts ==============================
platform linux -- Python 3.10.12, pytest-8.4.1, pluggy-1.6.0
rootdir: /home/codex/schofield
plugins: mock-3.14.1, anyio-4.9.0, cov-6.2.1, langsmith-0.4.1
collected 27 items / 1 error

==================================== ERRORS ====================================
____ ERROR collecting tests/functional/test_epic_a_data_model_functional.py ____
../.local/lib/python3.10/site-packages/_pytest/python.py:498: in importtestmodule
    mod = import_path(
../.local/lib/python3.10/site-packages/_pytest/pathlib.py:587: in import_path
    importlib.import_module(module_name)
/usr/lib/python3.10/importlib/__init__.py:126: in import_module
    return _bootstrap._gcd_import(name[level:], package, level)
<frozen importlib._bootstrap>:1050: in _gcd_import
    ???
<frozen importlib._bootstrap>:1027: in _find_and_load
    ???
<frozen importlib._bootstrap>:1006: in _find_and_load_unlocked
    ???
<frozen importlib._bootstrap>:688: in _load_unlocked
    ???
../.local/lib/python3.10/site-packages/_pytest/assertion/rewrite.py:186: in exec_module
    exec(co, module.__dict__)
tests/functional/test_epic_a_data_model_functional.py:768: in <module>
    exec(src, scope)
E     File "<string>", line 8
E       pass
E       ^^^^
E   IndentationError: expected an indented block after class definition on line 7
=========================== short test summary info ============================
ERROR tests/functional/test_epic_a_data_model_functional.py
!!!!!!!!!!!!!!!!!!!! Interrupted: 1 error during collection !!!!!!!!!!!!!!!!!!!!
=============================== 1 error in 0.48s ===============================
