============================= test session starts ==============================
platform linux -- Python 3.10.12, pytest-8.4.1, pluggy-1.6.0
rootdir: /home/codex/schofield
plugins: mock-3.14.1, anyio-4.9.0, cov-6.2.1, langsmith-0.4.1
collected 27 items / 1 error

==================================== ERRORS ====================================
____ ERROR collecting tests/functional/test_epic_a_data_model_functional.py ____
tests/functional/test_epic_a_data_model_functional.py:2549: in <module>
    assert result.get("error", dict()).get("code") == "{code}", f"expected {{"{code}"}} got {result.get('error', {}).get('code')} for 7.2.2.{sec_id}"
E   NameError: name 'result' is not defined
=========================== short test summary info ============================
ERROR tests/functional/test_epic_a_data_model_functional.py - NameError: name 'result' is not defined
!!!!!!!!!!!!!!!!!!!! Interrupted: 1 error during collection !!!!!!!!!!!!!!!!!!!!
=============================== 1 error in 0.50s ===============================
